Workbook

Sheet COA
A1: Kode Akun | B1: Nama Akun | D1: Kode Akun | E1: Nama Akun
A2: Aset Lancar
A3: Kas & Bank | D3: Aset Lancar
A4: 1101 | B4: Kas | D4: 1101 | E4: Kas Kecil
A5: 1102 | B5: BRI 562 | D5: 1102 | E5: BRI 562
A6: 1103 | B6: BRI 568 | D6: 1103 | E6: BRI 568 | F6: Giro
A7: 1104 | B7: BRI 309 (Giro) | D7: 1104 | E7: Rekening Owner
A8: 1105 | B8: BTN 041 (Giro) | D8: 1105 | E8: Rekening Bapak Owner
A9: 1106 | B9: BNI 084 (Giro) | D9: 1103 | E9: Deposito Jangka Pendek
A10: 1107 | B10: Mandiri 669 (Giro) | D10: 1104 | E10: Piutang Usaha
A11: 1108 | B11: Rekening Owner | D11: 1105 | E11: Piutang Afiliasi
A12: 1109 | B12: BRI 560 | D12: 1105 | E12: Piutang Afiliasi
A13: Piutang | D13: 1106 | E13: Piutang Lain-lain
A14: 1201 | B14: Deposito Jangka Pendek | D14: 1107 | E14: Uang Muka Pembelian Tanah
A15: 1202 | B15: Piutang Usaha | D15: 1108 | E15: Persediaan Tanah dalam Pengembangan
A16: 1203 | B16: Piutang Afiliasi | D16: 1109 | E16: Persediaan Bangunan dalam Proses
A17: 1204 | B17: Piutang Lain-lain | D17: 1110 | E17: Persediaan Properti Siap Jual
A18: 1205 | B18: Uang Muka Pembelian Tanah | D18: 1111 | E18: Pajak Dibayar di Muka
A19: 1206 | B19: Uang Muka Pembelian Konveksi | D19: 1112 | E19: Biaya Dibayar di Muka
A20: 1207 | B20: Pajak Dibayar di Muka | D20: Jumlah Aset Lancar
A21: 1208 | B21: Biaya Dibayar di Muka | D21: Aset Tidak Lancar
A22: Persediaan | D22: 1201 | E22: Tanah dan Bangunan Investasi
A23: 1301 | B23: Persediaan Tanah dalam Pengembangan | D23: 1202 | E23: Gedung Kantor
A24: 1302 | B24: Persediaan Bangunan dalam Proses | D24: 1203 | E24: Akumulasi Penyusutan Gedung
A25: 1303 | B25: Persediaan Properti Siap Jual | D25: 1204 | E25: Peralatan dan Mesin | F25: inv kantor
A26: 1304 | B26: Persediaan Bahan Baku | D26: 1205 | E26: Akumulasi Penyusutan Peralatan
A27: 1305 | B27: Persediaan Barang dalam Proses | D27: 1206 | E27: Kendaraan Operasional
A28: 1306 | B28: Persediaan Barang Jadi | D28: 1207 | E28: Akumulasi Penyusutan Kendaraan
A29: Aset Tidak Lancar | D29: 1208 | E29: Aset Dalam Penyelesaian
A30: 1401 | B30: Tanah dan Bangunan Investasi | D30: 1209 | E30: Investasi Jangka Panjang
A31: 1402 | B31: Gedung Kantor | D31: 1210 | E31: Aset Tak Berwujud
A32: 1403 | B32: Akumulasi Penyusutan Gedung | D32: Jumlah Aset Tidak Lancar
A33: 1404 | B33: Peralatan dan Mesin | D33: Kewajiban Lancar
A34: 1405 | B34: Akumulasi Penyusutan Peralatan | D34: 2101 | E34: Hutang Usaha
A35: 1406 | B35: Kendaraan Operasional | D35: 2102 | E35: Hutang Pajak
A36: 1407 | B36: Akumulasi Penyusutan Kendaraan | D36: 2103 | E36: Hutang Subkon
A37: 1408 | B37: Inventaris Kantor | D37: 2103 | E37: Hutang Gaji
A38: 1409 | B38: Akumulasi Penyusutan Inventaris Kantor | D38: 2104 | E38: Hutang Bunga
A39: 1410 | B39: Aset Dalam Penyelesaian | D39: 2105 | E39: Uang Muka Penjualan Properti | F39: Afiliasi
A40: 1411 | B40: Investasi Jangka Panjang | D40: 2106 | E40: Biaya yang Masih Harus Dibayar
...

Sheet WS
B1: =C61/12 -> 1893000 | O1: 46161 | R1: 800000000
B2: Balance Sheet | C2: =IF(C52-C78<1,C78,"check again") -> 5.4541781e+09 | F2: =IF(F52-F78<>0,"check again",F78) -> 5.9156766e+09 | I2: =IF(I52-I78<>0,"check again",I78) -> 7.4776924e+09 | L2: =IF(L52-L78<>0,"check again",L78) -> 1.0256229e+10 | O2: =IF(O52-O78<>0,"check again",O78) -> 1.0762977e+10 | R2: =IF(R52-R78<>0,"check again",R78) -> check again | U2: =IF(U52-U78<>0,"check again",U78) -> check again | X2: =IF(X52-X78<>0,"check again",X78) -> check again | AA2: =IF(AA52-AA78<>0,"check again",AA78) -> check again | AD2: =IF(AD52-AD78<>0,"check again",AD78) -> check again | AG2: =IF(AG52-AG78<>0,"check again",AG78) -> check again | AJ2: =IF(AJ52-AJ78<>0,"check again",AJ78) -> check again | AM2: =IF(AM52-AM78<>0,"check again",AM78) -> check again
B3: Profit/Loss | C3: =C100-C150 -> 0 | F3: =F100-F150 -> -58760634 | I3: =I100-I150 -> -16202453 | L3: =L100-L150 -> 117664143 | O3: =O100-O150 -> 1194932519 | R3: =R100-R150 -> 1901304172 | U3: =U100-U150 -> 0 | X3: =X100-X150 -> 0 | AA3: =AA100-AA150 -> 0 | AD3: =AD100-AD150 -> 0 | AG3: =AG100-AG150 -> 0 | AJ3: =AJ100-AJ150 -> 0 | AM3: =AM100-AM150 -> 0 | AN3: =SUM(D3:AG3) -> 3138937747
A5: Kode Akun | B5: Nama Akun | C5: 2025 | D5: Mutasi | F5: 46023 | G5: Mutasi | I5: 46054 | J5: Mutasi | L5: 46082 | M5: Mutasi | O5: 46113 | P5: Mutasi | R5: 46143 | S5: Mutasi | U5: 46174 | V5: Mutasi | X5: 46204 | Y5: Mutasi | AA5: 46235 | AB5: Mutasi | AD5: 46266 | AE5: Mutasi | AG5: 46296 | AH5: Mutasi | AJ5: 46327 | AK5: Mutasi | AM5: 46357
D6: Debet | E6: Kredit | G6: Debet | H6: Kredit | J6: Debet | K6: Kredit | M6: Debet | N6: Kredit | P6: Debet | Q6: Kredit | S6: Debet | T6: Kredit | V6: Debet | W6: Kredit | Y6: Debet | Z6: Kredit | AB6: Debet | AC6: Kredit | AE6: Debet | AF6: Kredit | AH6: Debet | AI6: Kredit | AK6: Debet | AL6: Kredit
A7: Aset Lancar
A8: Kas & Bank
A9: 1101 | B9: Kas | C9: 0 | D9: =SUMIFS(JU!$H$5:$H$178,JU!$F$5:$F$178,WS!$A9) -> 0 | E9: =SUMIFS(JU!$K$5:$K$178,JU!$I$5:$I$178,WS!$A9) -> 0 | F9: =C9+D9-E9 -> 0 | G9: =SUMIFS(JU!$H$180:$H$440,JU!$F$180:$F$440,WS!$A9) -> 0 | H9: =SUMIFS(JU!$K$180:$K$440,JU!$I$180:$I$440,WS!$A9) -> 0 | I9: =F9+G9-H9 -> 0 | J9: =SUMIFS(JU!$H$441:$H$695,JU!$F$441:$F$695,WS!$A9) -> 0 | K9: =SUMIFS(JU!$K$441:$K$695,JU!$I$441:$I$695,WS!$A9) -> 0 | L9: =I9+J9-K9 -> 0 | M9: =SUMIFS(JU!$H$696:$H$1062,JU!$F$696:$F$1062,$A9) -> 0 | N9: =SUMIFS(JU!$K$696:$K$1062,JU!$I$696:$I$1062,WS!$A9) -> 0 | O9: =L9+M9-N9 -> 0 | P9: =SUMIFS(JU!$H$1063:$H$5007,JU!$F$1063:$F$5007,WS!$A9) -> 0 | Q9: =SUMIFS(JU!$K$1063:$K$5007,JU!$I$1063:$I$5007,WS!$A9) -> 0 | R9: =O9+P9-Q9 -> 0 | S9: =SUMIFS(JU!$H$5107:$H$5107,JU!$F$5107:$F$5107,WS!$A9) -> 0 | T9: =SUMIFS(JU!$K$5107:$K$5107,JU!$I$5107:$I$5107,WS!$A9) -> 0 | U9: =R9+S9-T9 -> 0 | V9: =SUMIFS(JU!$H$5107:$H$5107,JU!$F$5107:$F$5107,WS!$A9) -> 0 | W9: =SUMIFS(JU!$K$5107:$K$5107,JU!$I$5107:$I$5107,WS!$A9) -> 0 | X9: =U9+V9-W9 -> 0 | Y9: =SUMIFS(JU!$H$5107:$H$5107,JU!$F$5107:$F$5107,WS!$A9) -> 0 | Z9: =SUMIFS(JU!$K$5107:$K$5107,JU!$I$5107:$I$5107,WS!$A9) -> 0 | AA9: =X9+Y9-Z9 -> 0 | AB9: =SUMIFS(JU!$H$5107:$H$5107,JU!$F$5107:$F$5107,WS!$A9) -> 0 | AC9: =SUMIFS(JU!$K$5107:$K$5107,JU!$I$5107:$I$5107,WS!$A9) -> 0 | AD9: =AA9+AB9-AC9 -> 0 | AE9: =SUMIFS(JU!$H$5107:$H$5107,JU!$F$5107:$F$5107,WS!$A9) -> 0 | AF9: =SUMIFS(JU!$K$5107:$K$5107,JU!$I$5107:$I$5107,WS!$A9) -> 0 | AG9: =AD9+AE9-AF9 -> 0 | AH9: =SUMIFS(JU!$H$5107:$H$5107,JU!$F$5107:$F$5107,WS!$A9) -> 0 | AI9: =SUMIFS(JU!$K$5107:$K$5107,JU!$I$5107:$I$5107,WS!$A9) -> 0 | AJ9: =AG9+AH9-AI9 -> 0 | AK9: =SUMIFS(JU!$H$5107:$H$5107,JU!$F$5107:$F$5107,WS!$A9) -> 0 | AL9: =SUMIFS(JU!$K$5107:$K$5107,JU!$I$5107:$I$5107,WS!$A9) -> 0 | AM9: =AJ9+AK9-AL9 -> 0 | AN9: 446751 | AO9: =AG9-AN9 -> -446751
A10: 1102 | B10: BRI 562 | C10: 0 | D10: =SUMIFS(JU!$H$5:$H$178,JU!$F$5:$F$178,WS!$A10) -> 0 | E10: =SUMIFS(JU!$K$5:$K$178,JU!$I$5:$I$178,WS!$A10) -> 0 | F10: =C10+D10-E10 -> 0 | G10: =SUMIFS(JU!$H$180:$H$440,JU!$F$180:$F$440,WS!$A10) -> 0 | H10: =SUMIFS(JU!$K$180:$K$440,JU!$I$180:$I$440,WS!$A10) -> 0 | I10: =F10+G10-H10 -> 0 | J10: =SUMIFS(JU!$H$441:$H$695,JU!$F$441:$F$695,WS!$A10) -> 0 | K10: =SUMIFS(JU!$K$441:$K$695,JU!$I$441:$I$695,WS!$A10) -> 0 | L10: =I10+J10-K10 -> 0 | M10: =SUMIFS(JU!$H$696:$H$1062,JU!$F$696:$F$1062,$A10) -> 0 | N10: =SUMIFS(JU!$K$696:$K$1062,JU!$I$696:$I$1062,WS!$A10) -> 0 | O10: =L10+M10-N10 -> 0 | P10: =SUMIFS(JU!$H$1063:$H$5007,JU!$F$1063:$F$5007,WS!$A10) -> 0 | Q10: =SUMIFS(JU!$K$1063:$K$5007,JU!$I$1063:$I$5007,WS!$A10) -> 0 | R10: =O10+P10-Q10 -> 0 | S10: =SUMIFS(JU!$H$5107:$H$5107,JU!$F$5107:$F$5107,WS!$A10) -> 0 | T10: =SUMIFS(JU!$K$5107:$K$5107,JU!$I$5107:$I$5107,WS!$A10) -> 0 | U10: =R10+S10-T10 -> 0 | V10: =SUMIFS(JU!$H$5107:$H$5107,JU!$F$5107:$F$5107,WS!$A10) -> 0 | W10: =SUMIFS(JU!$K$5107:$K$5107,JU!$I$5107:$I$5107,WS!$A10) -> 0 | X10: =U10+V10-W10 -> 0 | Y10: =SUMIFS(JU!$H$5107:$H$5107,JU!$F$5107:$F$5107,WS!$A10) -> 0 | Z10: =SUMIFS(JU!$K$5107:$K$5107,JU!$I$5107:$I$5107,WS!$A10) -> 0 | AA10: =X10+Y10-Z10 -> 0 | AB10: =SUMIFS(JU!$H$5107:$H$5107,JU!$F$5107:$F$5107,WS!$A10) -> 0 | AC10: =SUMIFS(JU!$K$5107:$K$5107,JU!$I$5107:$I$5107,WS!$A10) -> 0 | AD10: =AA10+AB10-AC10 -> 0 | AE10: =SUMIFS(JU!$H$5107:$H$5107,JU!$F$5107:$F$5107,WS!$A10) -> 0 | AF10: =SUMIFS(JU!$K$5107:$K$5107,JU!$I$5107:$I$5107,WS!$A10) -> 0 | AG10: =AD10+AE10-AF10 -> 0 | AH10: =SUMIFS(JU!$H$5107:$H$5107,JU!$F$5107:$F$5107,WS!$A10) -> 0 | AI10: =SUMIFS(JU!$K$5107:$K$5107,JU!$I$5107:$I$5107,WS!$A10) -> 0 | AJ10: =AG10+AH10-AI10 -> 0 | AK10: =SUMIFS(JU!$H$5107:$H$5107,JU!$F$5107:$F$5107,WS!$A10) -> 0 | AL10: =SUMIFS(JU!$K$5107:$K$5107,JU!$I$5107:$I$5107,WS!$A10) -> 0 | AM10: =AJ10+AK10-AL10 -> 0 | AN10: Saldo Real RK | AO10: Selisih
A11: 1103 | B11: BRI 568 | C11: 14931577 | D11: =SUMIFS(JU!$H$5:$H$178,JU!$F$5:$F$178,WS!$A11) -> 1897877594 | E11: =SUMIFS(JU!$K$5:$K$178,JU!$I$5:$I$178,WS!$A11) -> 1909356910 | F11: =C11+D11-E11 -> 3452261.2 | G11: =SUMIFS(JU!$H$180:$H$440,JU!$F$180:$F$440,WS!$A11) -> 5508497990 | H11: =SUMIFS(JU!$K$180:$K$440,JU!$I$180:$I$440,WS!$A11) -> 5467947247 | I11: =F11+G11-H11 -> 44003004 | J11: =SUMIFS(JU!$H$441:$H$695,JU!$F$441:$F$695,WS!$A11) -> 3718534853 | K11: =SUMIFS(JU!$K$441:$K$695,JU!$I$441:$I$695,WS!$A11) -> 3745432928 | L11: =I11+J11-K11 -> 17104929 | M11: =SUMIFS(JU!$H$696:$H$1062,JU!$F$696:$F$1062,$A11) -> 5526256754 | N11: =SUMIFS(JU!$K$696:$K$1062,JU!$I$696:$I$1062,WS!$A11) -> 5539476187 | O11: =L11+M11-N11 -> 3885496.2 | P11: =SUMIFS(JU!$H$1063:$H$5007,JU!$F$1063:$F$5007,WS!$A11) -> 4770567500 | Q11: =SUMIFS(JU!$K$1063:$K$5007,JU!$I$1063:$I$5007,WS!$A11) -> 4717910456 | R11: =O11+P11-Q11 -> 56542540 | S11: =SUMIFS(JU!$H$5107:$H$5107,JU!$F$5107:$F$5107,WS!$A11) -> 0 | T11: =SUMIFS(JU!$K$5107:$K$5107,JU!$I$5107:$I$5107,WS!$A11) -> 0 | U11: =R11+S11-T11 -> 56542540 | V11: =SUMIFS(JU!$H$5107:$H$5107,JU!$F$5107:$F$5107,WS!$A11) -> 0 | W11: =SUMIFS(JU!$K$5107:$K$5107,JU!$I$5107:$I$5107,WS!$A11) -> 0 | X11: =U11+V11-W11 -> 56542540 | Y11: =SUMIFS(JU!$H$5107:$H$5107,JU!$F$5107:$F$5107,WS!$A11) -> 0 | Z11: =SUMIFS(JU!$K$5107:$K$5107,JU!$I$5107:$I$5107,WS!$A11) -> 0 | AA11: =X11+Y11-Z11 -> 56542540 | AB11: =SUMIFS(JU!$H$5107:$H$5107,JU!$F$5107:$F$5107,WS!$A11) -> 0 | AC11: =SUMIFS(JU!$K$5107:$K$5107,JU!$I$5107:$I$5107,WS!$A11) -> 0 | AD11: =AA11+AB11-AC11 -> 56542540 | AE11: =SUMIFS(JU!$H$5107:$H$5107,JU!$F$5107:$F$5107,WS!$A11) -> 0 | AF11: =SUMIFS(JU!$K$5107:$K$5107,JU!$I$5107:$I$5107,WS!$A11) -> 0 | AG11: =AD11+AE11-AF11 -> 56542540 | AH11: =SUMIFS(JU!$H$5107:$H$5107,JU!$F$5107:$F$5107,WS!$A11) -> 0 | AI11: =SUMIFS(JU!$K$5107:$K$5107,JU!$I$5107:$I$5107,WS!$A11) -> 0 | AJ11: =AG11+AH11-AI11 -> 56542540 | AK11: =SUMIFS(JU!$H$5107:$H$5107,JU!$F$5107:$F$5107,WS!$A11) -> 0 | AL11: =SUMIFS(JU!$K$5107:$K$5107,JU!$I$5107:$I$5107,WS!$A11) -> 0 | AM11: =AJ11+AK11-AL11 -> 56542540 | AN11: 311777388 | AO11: =AG11-AN11 -> -2.5523485e+08
A12: 1104 | B12: BRI 309 (Giro) | C12: 26000000 | D12: =SUMIFS(JU!$H$5:$H$178,JU!$F$5:$F$178,WS!$A12) -> 0 | E12: =SUMIFS(JU!$K$5:$K$178,JU!$I$5:$I$178,WS!$A12) -> 0 | F12: =C12+D12-E12 -> 26000000 | G12: =SUMIFS(JU!$H$180:$H$440,JU!$F$180:$F$440,WS!$A12) -> 0 | H12: =SUMIFS(JU!$K$180:$K$440,JU!$I$180:$I$440,WS!$A12) -> 0 | I12: =F12+G12-H12 -> 26000000 | J12: =SUMIFS(JU!$H$441:$H$695,JU!$F$441:$F$695,WS!$A12) -> 0 | K12: =SUMIFS(JU!$K$441:$K$695,JU!$I$441:$I$695,WS!$A12) -> 0 | L12: =I12+J12-K12 -> 26000000 | M12: =SUMIFS(JU!$H$696:$H$1062,JU!$F$696:$F$1062,$A12) -> 0 | N12: =SUMIFS(JU!$K$696:$K$1062,JU!$I$696:$I$1062,WS!$A12) -> 0 | O12: =L12+M12-N12 -> 26000000 | P12: =SUMIFS(JU!$H$1063:$H$5007,JU!$F$1063:$F$5007,WS!$A12) -> 0 | Q12: =SUMIFS(JU!$K$1063:$K$5007,JU!$I$1063:$I$5007,WS!$A12) -> 0 | R12: =O12+P12-Q12 -> 26000000 | S12: =SUMIFS(JU!$H$5107:$H$5107,JU!$F$5107:$F$5107,WS!$A12) -> 0 | T12: =SUMIFS(JU!$K$5107:$K$5107,JU!$I$5107:$I$5107,WS!$A12) -> 0 | U12: =R12+S12-T12 -> 26000000 | V12: =SUMIFS(JU!$H$5107:$H$5107,JU!$F$5107:$F$5107,WS!$A12) -> 0 | W12: =SUMIFS(JU!$K$5107:$K$5107,JU!$I$5107:$I$5107,WS!$A12) -> 0 | X12: =U12+V12-W12 -> 26000000 | Y12: =SUMIFS(JU!$H$5107:$H$5107,JU!$F$5107:$F$5107,WS!$A12) -> 0 | Z12: =SUMIFS(JU!$K$5107:$K$5107,JU!$I$5107:$I$5107,WS!$A12) -> 0 | AA12: =X12+Y12-Z12 -> 26000000 | AB12: =SUMIFS(JU!$H$5107:$H$5107,JU!$F$5107:$F$5107,WS!$A12) -> 0 | AC12: =SUMIFS(JU!$K$5107:$K$5107,JU!$I$5107:$I$5107,WS!$A12) -> 0 | AD12: =AA12+AB12-AC12 -> 26000000 | AE12: =SUMIFS(JU!$H$5107:$H$5107,JU!$F$5107:$F$5107,WS!$A12) -> 0 | AF12: =SUMIFS(JU!$K$5107:$K$5107,JU!$I$5107:$I$5107,WS!$A12) -> 0 | AG12: =AD12+AE12-AF12 -> 26000000 | AH12: =SUMIFS(JU!$H$5107:$H$5107,JU!$F$5107:$F$5107,WS!$A12) -> 0 | AI12: =SUMIFS(JU!$K$5107:$K$5107,JU!$I$5107:$I$5107,WS!$A12) -> 0 | AJ12: =AG12+AH12-AI12 -> 26000000 | AK12: =SUMIFS(JU!$H$5107:$H$5107,JU!$F$5107:$F$5107,WS!$A12) -> 0 | AL12: =SUMIFS(JU!$K$5107:$K$5107,JU!$I$5107:$I$5107,WS!$A12) -> 0 | AM12: =AJ12+AK12-AL12 -> 26000000
A13: 1105 | B13: BTN 041 (Giro) | C13: 0 | D13: =SUMIFS(JU!$H$5:$H$178,JU!$F$5:$F$178,WS!$A13) -> 0 | E13: =SUMIFS(JU!$K$5:$K$178,JU!$I$5:$I$178,WS!$A13) -> 0 | F13: =C13+D13-E13 -> 0 | G13: =SUMIFS(JU!$H$180:$H$440,JU!$F$180:$F$440,WS!$A13) -> 0 | H13: =SUMIFS(JU!$K$180:$K$440,JU!$I$180:$I$440,WS!$A13) -> 0 | I13: =F13+G13-H13 -> 0 | J13: =SUMIFS(JU!$H$441:$H$695,JU!$F$441:$F$695,WS!$A13) -> 0 | K13: =SUMIFS(JU!$K$441:$K$695,JU!$I$441:$I$695,WS!$A13) -> 0 | L13: =I13+J13-K13 -> 0 | M13: =SUMIFS(JU!$H$696:$H$1062,JU!$F$696:$F$1062,$A13) -> 0 | N13: =SUMIFS(JU!$K$696:$K$1062,JU!$I$696:$I$1062,WS!$A13) -> 0 | O13: =L13+M13-N13 -> 0 | P13: =SUMIFS(JU!$H$1063:$H$5007,JU!$F$1063:$F$5007,WS!$A13) -> 0 | Q13: =SUMIFS(JU!$K$1063:$K$5007,JU!$I$1063:$I$5007,WS!$A13) -> 0 | R13: =O13+P13-Q13 -> 0 | S13: =SUMIFS(JU!$H$5107:$H$5107,JU!$F$5107:$F$5107,WS!$A13) -> 0 | T13: =SUMIFS(JU!$K$5107:$K$5107,JU!$I$5107:$I$5107,WS!$A13) -> 0 | U13: =R13+S13-T13 -> 0 | V13: =SUMIFS(JU!$H$5107:$H$5107,JU!$F$5107:$F$5107,WS!$A13) -> 0 | W13: =SUMIFS(JU!$K$5107:$K$5107,JU!$I$5107:$I$5107,WS!$A13) -> 0 | X13: =U13+V13-W13 -> 0 | Y13: =SUMIFS(JU!$H$5107:$H$5107,JU!$F$5107:$F$5107,WS!$A13) -> 0 | Z13: =SUMIFS(JU!$K$5107:$K$5107,JU!$I$5107:$I$5107,WS!$A13) -> 0 | AA13: =X13+Y13-Z13 -> 0 | AB13: =SUMIFS(JU!$H$5107:$H$5107,JU!$F$5107:$F$5107,WS!$A13) -> 0 | AC13: =SUMIFS(JU!$K$5107:$K$5107,JU!$I$5107:$I$5107,WS!$A13) -> 0 | AD13: =AA13+AB13-AC13 -> 0 | AE13: =SUMIFS(JU!$H$5107:$H$5107,JU!$F$5107:$F$5107,WS!$A13) -> 0 | AF13: =SUMIFS(JU!$K$5107:$K$5107,JU!$I$5107:$I$5107,WS!$A13) -> 0 | AG13: =AD13+AE13-AF13 -> 0 | AH13: =SUMIFS(JU!$H$5107:$H$5107,JU!$F$5107:$F$5107,WS!$A13) -> 0 | AI13: =SUMIFS(JU!$K$5107:$K$5107,JU!$I$5107:$I$5107,WS!$A13) -> 0 | AJ13: =AG13+AH13-AI13 -> 0 | AK13: =SUMIFS(JU!$H$5107:$H$5107,JU!$F$5107:$F$5107,WS!$A13) -> 0 | AL13: =SUMIFS(JU!$K$5107:$K$5107,JU!$I$5107:$I$5107,WS!$A13) -> 0 | AM13: =AJ13+AK13-AL13 -> 0
A14: 1106 | B14: BNI 084 (Giro) | C14: 0 | D14: =SUMIFS(JU!$H$5:$H$178,JU!$F$5:$F$178,WS!$A14) -> 0 | E14: =SUMIFS(JU!$K$5:$K$178,JU!$I$5:$I$178,WS!$A14) -> 0 | F14: =C14+D14-E14 -> 0 | G14: =SUMIFS(JU!$H$180:$H$440,JU!$F$180:$F$440,WS!$A14) -> 0 | H14: =SUMIFS(JU!$K$180:$K$440,JU!$I$180:$I$440,WS!$A14) -> 0 | I14: =F14+G14-H14 -> 0 | J14: =SUMIFS(JU!$H$441:$H$695,JU!$F$441:$F$695,WS!$A14) -> 0 | K14: =SUMIFS(JU!$K$441:$K$695,JU!$I$441:$I$695,WS!$A14) -> 0 | L14: =I14+J14-K14 -> 0 | M14: =SUMIFS(JU!$H$696:$H$1062,JU!$F$696:$F$1062,$A14) -> 0 | N14: =SUMIFS(JU!$K$696:$K$1062,JU!$I$696:$I$1062,WS!$A14) -> 0 | O14: =L14+M14-N14 -> 0 | P14: =SUMIFS(JU!$H$1063:$H$5007,JU!$F$1063:$F$5007,WS!$A14) -> 0 | Q14: =SUMIFS(JU!$K$1063:$K$5007,JU!$I$1063:$I$5007,WS!$A14) -> 0 | R14: =O14+P14-Q14 -> 0 | S14: =SUMIFS(JU!$H$5107:$H$5107,JU!$F$5107:$F$5107,WS!$A14) -> 0 | T14: =SUMIFS(JU!$K$5107:$K$5107,JU!$I$5107:$I$5107,WS!$A14) -> 0 | U14: =R14+S14-T14 -> 0 | V14: =SUMIFS(JU!$H$5107:$H$5107,JU!$F$5107:$F$5107,WS!$A14) -> 0 | W14: =SUMIFS(JU!$K$5107:$K$5107,JU!$I$5107:$I$5107,WS!$A14) -> 0 | X14: =U14+V14-W14 -> 0 | Y14: =SUMIFS(JU!$H$5107:$H$5107,JU!$F$5107:$F$5107,WS!$A14) -> 0 | Z14: =SUMIFS(JU!$K$5107:$K$5107,JU!$I$5107:$I$5107,WS!$A14) -> 0 | AA14: =X14+Y14-Z14 -> 0 | AB14: =SUMIFS(JU!$H$5107:$H$5107,JU!$F$5107:$F$5107,WS!$A14) -> 0 | AC14: =SUMIFS(JU!$K$5107:$K$5107,JU!$I$5107:$I$5107,WS!$A14) -> 0 | AD14: =AA14+AB14-AC14 -> 0 | AE14: =SUMIFS(JU!$H$5107:$H$5107,JU!$F$5107:$F$5107,WS!$A14) -> 0 | AF14: =SUMIFS(JU!$K$5107:$K$5107,JU!$I$5107:$I$5107,WS!$A14) -> 0 | AG14: =AD14+AE14-AF14 -> 0 | AH14: =SUMIFS(JU!$H$5107:$H$5107,JU!$F$5107:$F$5107,WS!$A14) -> 0 | AI14: =SUMIFS(JU!$K$5107:$K$5107,JU!$I$5107:$I$5107,WS!$A14) -> 0 | AJ14: =AG14+AH14-AI14 -> 0 | AK14: =SUMIFS(JU!$H$5107:$H$5107,JU!$F$5107:$F$5107,WS!$A14) -> 0 | AL14: =SUMIFS(JU!$K$5107:$K$5107,JU!$I$5107:$I$5107,WS!$A14) -> 0 | AM14: =AJ14+AK14-AL14 -> 0
A15: 1107 | B15: Mandiri 669 (Giro) | C15: 0 | D15: =SUMIFS(JU!$H$5:$H$178,JU!$F$5:$F$178,WS!$A15) -> 0 | E15: =SUMIFS(JU!$K$5:$K$178,JU!$I$5:$I$178,WS!$A15) -> 0 | F15: =C15+D15-E15 -> 0 | G15: =SUMIFS(JU!$H$180:$H$440,JU!$F$180:$F$440,WS!$A15) -> 0 | H15: =SUMIFS(JU!$K$180:$K$440,JU!$I$180:$I$440,WS!$A15) -> 0 | I15: =F15+G15-H15 -> 0 | J15: =SUMIFS(JU!$H$441:$H$695,JU!$F$441:$F$695,WS!$A15) -> 0 | K15: =SUMIFS(JU!$K$441:$K$695,JU!$I$441:$I$695,WS!$A15) -> 0 | L15: =I15+J15-K15 -> 0 | M15: =SUMIFS(JU!$H$696:$H$1062,JU!$F$696:$F$1062,$A15) -> 0 | N15: =SUMIFS(JU!$K$696:$K$1062,JU!$I$696:$I$1062,WS!$A15) -> 0 | O15: =L15+M15-N15 -> 0 | P15: =SUMIFS(JU!$H$1063:$H$5007,JU!$F$1063:$F$5007,WS!$A15) -> 0 | Q15: =SUMIFS(JU!$K$1063:$K$5007,JU!$I$1063:$I$5007,WS!$A15) -> 0 | R15: =O15+P15-Q15 -> 0 | S15: =SUMIFS(JU!$H$5107:$H$5107,JU!$F$5107:$F$5107,WS!$A15) -> 0 | T15: =SUMIFS(JU!$K$5107:$K$5107,JU!$I$5107:$I$5107,WS!$A15) -> 0 | U15: =R15+S15-T15 -> 0 | V15: =SUMIFS(JU!$H$5107:$H$5107,JU!$F$5107:$F$5107,WS!$A15) -> 0 | W15: =SUMIFS(JU!$K$5107:$K$5107,JU!$I$5107:$I$5107,WS!$A15) -> 0 | X15: =U15+V15-W15 -> 0 | Y15: =SUMIFS(JU!$H$5107:$H$5107,JU!$F$5107:$F$5107,WS!$A15) -> 0 | Z15: =SUMIFS(JU!$K$5107:$K$5107,JU!$I$5107:$I$5107,WS!$A15) -> 0 | AA15: =X15+Y15-Z15 -> 0 | AB15: =SUMIFS(JU!$H$5107:$H$5107,JU!$F$5107:$F$5107,WS!$A15) -> 0 | AC15: =SUMIFS(JU!$K$5107:$K$5107,JU!$I$5107:$I$5107,WS!$A15) -> 0 | AD15: =AA15+AB15-AC15 -> 0 | AE15: =SUMIFS(JU!$H$5107:$H$5107,JU!$F$5107:$F$5107,WS!$A15) -> 0 | AF15: =SUMIFS(JU!$K$5107:$K$5107,JU!$I$5107:$I$5107,WS!$A15) -> 0 | AG15: =AD15+AE15-AF15 -> 0 | AH15: =SUMIFS(JU!$H$5107:$H$5107,JU!$F$5107:$F$5107,WS!$A15) -> 0 | AI15: =SUMIFS(JU!$K$5107:$K$5107,JU!$I$5107:$I$5107,WS!$A15) -> 0 | AJ15: =AG15+AH15-AI15 -> 0 | AK15: =SUMIFS(JU!$H$5107:$H$5107,JU!$F$5107:$F$5107,WS!$A15) -> 0 | AL15: =SUMIFS(JU!$K$5107:$K$5107,JU!$I$5107:$I$5107,WS!$A15) -> 0 | AM15: =AJ15+AK15-AL15 -> 0
A16: 1108 | B16: Rekening Owner | C16: 144518 | D16: =SUMIFS(JU!$H$5:$H$178,JU!$F$5:$F$178,WS!$A16) -> 0 | E16: =SUMIFS(JU!$K$5:$K$178,JU!$I$5:$I$178,WS!$A16) -> 0 | F16: =C16+D16-E16 -> 144518 | G16: =SUMIFS(JU!$H$180:$H$440,JU!$F$180:$F$440,WS!$A16) -> 200000000 | H16: =SUMIFS(JU!$K$180:$K$440,JU!$I$180:$I$440,WS!$A16) -> 0 | I16: =F16+G16-H16 -> 200144518 | J16: =SUMIFS(JU!$H$441:$H$695,JU!$F$441:$F$695,WS!$A16) -> 1200000000 | K16: =SUMIFS(JU!$K$441:$K$695,JU!$I$441:$I$695,WS!$A16) -> 200000000 | L16: =I16+J16-K16 -> 1200144518 | M16: =SUMIFS(JU!$H$696:$H$1062,JU!$F$696:$F$1062,$A16) -> 420000000 | N16: =SUMIFS(JU!$K$696:$K$1062,JU!$I$696:$I$1062,WS!$A16) -> 1184000000 | O16: =L16+M16-N16 -> 436144518 | P16: =SUMIFS(JU!$H$1063:$H$5007,JU!$F$1063:$F$5007,WS!$A16) -> 1190000000 | Q16: =SUMIFS(JU!$K$1063:$K$5007,JU!$I$1063:$I$5007,WS!$A16) -> 835000000 | R16: =O16+P16-Q16 -> 791144518 | S16: =SUMIFS(JU!$H$5107:$H$5107,JU!$F$5107:$F$5107,WS!$A16) -> 0 | T16: =SUMIFS(JU!$K$5107:$K$5107,JU!$I$5107:$I$5107,WS!$A16) -> 0 | U16: =R16+S16-T16 -> 791144518 | V16: =SUMIFS(JU!$H$5107:$H$5107,JU!$F$5107:$F$5107,WS!$A16) -> 0 | W16: =SUMIFS(JU!$K$5107:$K$5107,JU!$I$5107:$I$5107,WS!$A16) -> 0 | X16: =U16+V16-W16 -> 791144518 | Y16: =SUMIFS(JU!$H$5107:$H$5107,JU!$F$5107:$F$5107,WS!$A16) -> 0 | Z16: =SUMIFS(JU!$K$5107:$K$5107,JU!$I$5107:$I$5107,WS!$A16) -> 0 | AA16: =X16+Y16-Z16 -> 791144518 | AB16: =SUMIFS(JU!$H$5107:$H$5107,JU!$F$5107:$F$5107,WS!$A16) -> 0 | AC16: =SUMIFS(JU!$K$5107:$K$5107,JU!$I$5107:$I$5107,WS!$A16) -> 0 | AD16: =AA16+AB16-AC16 -> 791144518 | AE16: =SUMIFS(JU!$H$5107:$H$5107,JU!$F$5107:$F$5107,WS!$A16) -> 0 | AF16: =SUMIFS(JU!$K$5107:$K$5107,JU!$I$5107:$I$5107,WS!$A16) -> 0 | AG16: =AD16+AE16-AF16 -> 791144518 | AH16: =SUMIFS(JU!$H$5107:$H$5107,JU!$F$5107:$F$5107,WS!$A16) -> 0 | AI16: =SUMIFS(JU!$K$5107:$K$5107,JU!$I$5107:$I$5107,WS!$A16) -> 0 | AJ16: =AG16+AH16-AI16 -> 791144518 | AK16: =SUMIFS(JU!$H$5107:$H$5107,JU!$F$5107:$F$5107,WS!$A16) -> 0 | AL16: =SUMIFS(JU!$K$5107:$K$5107,JU!$I$5107:$I$5107,WS!$A16) -> 0 | AM16: =AJ16+AK16-AL16 -> 791144518
A17: 1109 | B17: BRI 560 | C17: 0 | D17: =SUMIFS(JU!$H$5:$H$178,JU!$F$5:$F$178,WS!$A17) -> 0 | E17: =SUMIFS(JU!$K$5:$K$178,JU!$I$5:$I$178,WS!$A17) -> 0 | F17: =C17+D17-E17 -> 0 | G17: =SUMIFS(JU!$H$180:$H$440,JU!$F$180:$F$440,WS!$A17) -> 0 | H17: =SUMIFS(JU!$K$180:$K$440,JU!$I$180:$I$440,WS!$A17) -> 0 | I17: =F17+G17-H17 -> 0 | J17: =SUMIFS(JU!$H$441:$H$695,JU!$F$441:$F$695,WS!$A17) -> 0 | K17: =SUMIFS(JU!$K$441:$K$695,JU!$I$441:$I$695,WS!$A17) -> 0 | L17: =I17+J17-K17 -> 0 | M17: =SUMIFS(JU!$H$696:$H$1062,JU!$F$696:$F$1062,$A17) -> 0 | N17: =SUMIFS(JU!$K$696:$K$1062,JU!$I$696:$I$1062,WS!$A17) -> 0 | O17: =L17+M17-N17 -> 0 | P17: =SUMIFS(JU!$H$1063:$H$5007,JU!$F$1063:$F$5007,WS!$A17) -> 0 | Q17: =SUMIFS(JU!$K$1063:$K$5007,JU!$I$1063:$I$5007,WS!$A17) -> 0 | R17: =O17+P17-Q17 -> 0 | S17: =SUMIFS(JU!$H$5107:$H$5107,JU!$F$5107:$F$5107,WS!$A17) -> 0 | T17: =SUMIFS(JU!$K$5107:$K$5107,JU!$I$5107:$I$5107,WS!$A17) -> 0 | U17: =R17+S17-T17 -> 0 | V17: =SUMIFS(JU!$H$5107:$H$5107,JU!$F$5107:$F$5107,WS!$A17) -> 0 | W17: =SUMIFS(JU!$K$5107:$K$5107,JU!$I$5107:$I$5107,WS!$A17) -> 0 | X17: =U17+V17-W17 -> 0 | Y17: =SUMIFS(JU!$H$5107:$H$5107,JU!$F$5107:$F$5107,WS!$A17) -> 0 | Z17: =SUMIFS(JU!$K$5107:$K$5107,JU!$I$5107:$I$5107,WS!$A17) -> 0 | AA17: =X17+Y17-Z17 -> 0 | AB17: =SUMIFS(JU!$H$5107:$H$5107,JU!$F$5107:$F$5107,WS!$A17) -> 0 | AC17: =SUMIFS(JU!$K$5107:$K$5107,JU!$I$5107:$I$5107,WS!$A17) -> 0 | AD17: =AA17+AB17-AC17 -> 0 | AE17: =SUMIFS(JU!$H$5107:$H$5107,JU!$F$5107:$F$5107,WS!$A17) -> 0 | AF17: =SUMIFS(JU!$K$5107:$K$5107,JU!$I$5107:$I$5107,WS!$A17) -> 0 | AG17: =AD17+AE17-AF17 -> 0 | AH17: =SUMIFS(JU!$H$5107:$H$5107,JU!$F$5107:$F$5107,WS!$A17) -> 0 | AI17: =SUMIFS(JU!$K$5107:$K$5107,JU!$I$5107:$I$5107,WS!$A17) -> 0 | AJ17: =AG17+AH17-AI17 -> 0 | AK17: =SUMIFS(JU!$H$5107:$H$5107,JU!$F$5107:$F$5107,WS!$A17) -> 0 | AL17: =SUMIFS(JU!$K$5107:$K$5107,JU!$I$5107:$I$5107,WS!$A17) -> 0 | AM17: =AJ17+AK17-AL17 -> 0 | AN17: 58428285 | AO17: =AG17-AN17 -> -58428285
A18: Total Kas & Bank | C18: =SUM(C9:C17) -> 41076095 | D18: =SUMIFS(JU!$H$5:$H$178,JU!$F$5:$F$178,WS!$A18) -> 0 | E18: =SUMIFS(JU!$K$5:$K$178,JU!$I$5:$I$178,WS!$A18) -> 0 | F18: =SUM(F9:F17) -> 29596779 | G18: =SUMIFS(JU!$H$180:$H$440,JU!$F$180:$F$440,WS!$A18) -> 0 | H18: =SUMIFS(JU!$K$180:$K$440,JU!$I$180:$I$440,WS!$A18) -> 0 | I18: =SUM(I9:I17) -> 2.7014752e+08 | J18: =SUMIFS(JU!$H$441:$H$695,JU!$F$441:$F$695,WS!$A18) -> 0 | K18: =SUMIFS(JU!$K$441:$K$695,JU!$I$441:$I$695,WS!$A18) -> 0 | L18: =SUM(L9:L17) -> 1.2432494e+09 | M18: =SUMIFS(JU!$H$696:$H$1062,JU!$F$696:$F$1062,$A18) -> 0 | N18: =SUMIFS(JU!$K$696:$K$1062,JU!$I$696:$I$1062,WS!$A18) -> 0 | O18: =SUM(O9:O17) -> 4.6603001e+08 | P18: =SUMIFS(JU!$H$1063:$H$5007,JU!$F$1063:$F$5007,WS!$A18) -> 0 | Q18: =SUMIFS(JU!$K$1063:$K$5007,JU!$I$1063:$I$5007,WS!$A18) -> 0 | R18: =SUM(R9:R17) -> 8.7368706e+08 | S18: =SUMIFS(JU!$H$5107:$H$5107,JU!$F$5107:$F$5107,WS!$A18) -> 0 | T18: =SUMIFS(JU!$K$5107:$K$5107,JU!$I$5107:$I$5107,WS!$A18) -> 0 | U18: =SUM(U9:U17) -> 8.7368706e+08 | V18: =SUMIFS(JU!$H$5107:$H$5107,JU!$F$5107:$F$5107,WS!$A18) -> 0 | W18: =SUMIFS(JU!$K$5107:$K$5107,JU!$I$5107:$I$5107,WS!$A18) -> 0 | X18: =SUM(X9:X17) -> 8.7368706e+08 | Y18: =SUMIFS(JU!$H$5107:$H$5107,JU!$F$5107:$F$5107,WS!$A18) -> 0 | Z18: =SUMIFS(JU!$K$5107:$K$5107,JU!$I$5107:$I$5107,WS!$A18) -> 0 | AA18: =SUM(AA9:AA17) -> 8.7368706e+08 | AB18: =SUMIFS(JU!$H$5107:$H$5107,JU!$F$5107:$F$5107,WS!$A18) -> 0 | AC18: =SUMIFS(JU!$K$5107:$K$5107,JU!$I$5107:$I$5107,WS!$A18) -> 0 | AD18: =SUM(AD9:AD17) -> 8.7368706e+08 | AE18: =SUMIFS(JU!$H$5107:$H$5107,JU!$F$5107:$F$5107,WS!$A18) -> 0 | AF18: =SUMIFS(JU!$K$5107:$K$5107,JU!$I$5107:$I$5107,WS!$A18) -> 0 | AG18: =SUM(AG9:AG17) -> 8.7368706e+08 | AH18: =SUMIFS(JU!$H$5107:$H$5107,JU!$F$5107:$F$5107,WS!$A18) -> 0 | AI18: =SUMIFS(JU!$K$5107:$K$5107,JU!$I$5107:$I$5107,WS!$A18) -> 0 | AJ18: =SUM(AJ9:AJ17) -> 8.7368706e+08 | AK18: =SUMIFS(JU!$H$5107:$H$5107,JU!$F$5107:$F$5107,WS!$A18) -> 0 | AL18: =SUMIFS(JU!$K$5107:$K$5107,JU!$I$5107:$I$5107,WS!$A18) -> 0 | AM18: =SUM(AM9:AM17) -> 8.7368706e+08
A19: Piutang | D19: =SUMIFS(JU!$H$5:$H$178,JU!$F$5:$F$178,WS!$A19) -> 0 | E19: =SUMIFS(JU!$K$5:$K$178,JU!$I$5:$I$178,WS!$A19) -> 0 | G19: =SUMIFS(JU!$H$180:$H$440,JU!$F$180:$F$440,WS!$A19) -> 0 | H19: =SUMIFS(JU!$K$180:$K$440,JU!$I$180:$I$440,WS!$A19) -> 0 | J19: =SUMIFS(JU!$H$441:$H$695,JU!$F$441:$F$695,WS!$A19) -> 0 | K19: =SUMIFS(JU!$K$441:$K$695,JU!$I$441:$I$695,WS!$A19) -> 0 | M19: =SUMIFS(JU!$H$696:$H$1062,JU!$F$696:$F$1062,$A19) -> 0 | N19: =SUMIFS(JU!$K$696:$K$1062,JU!$I$696:$I$1062,WS!$A19) -> 0 | P19: =SUMIFS(JU!$H$1063:$H$5007,JU!$F$1063:$F$5007,WS!$A19) -> 0 | Q19: =SUMIFS(JU!$K$1063:$K$5007,JU!$I$1063:$I$5007,WS!$A19) -> 0 | S19: =SUMIFS(JU!$H$5107:$H$5107,JU!$F$5107:$F$5107,WS!$A19) -> 0 | T19: =SUMIFS(JU!$K$5107:$K$5107,JU!$I$5107:$I$5107,WS!$A19) -> 0 | V19: =SUMIFS(JU!$H$5107:$H$5107,JU!$F$5107:$F$5107,WS!$A19) -> 0 | W19: =SUMIFS(JU!$K$5107:$K$5107,JU!$I$5107:$I$5107,WS!$A19) -> 0 | Y19: =SUMIFS(JU!$H$5107:$H$5107,JU!$F$5107:$F$5107,WS!$A19) -> 0 | Z19: =SUMIFS(JU!$K$5107:$K$5107,JU!$I$5107:$I$5107,WS!$A19) -> 0 | AB19: =SUMIFS(JU!$H$5107:$H$5107,JU!$F$5107:$F$5107,WS!$A19) -> 0 | AC19: =SUMIFS(JU!$K$5107:$K$5107,JU!$I$5107:$I$5107,WS!$A19) -> 0 | AE19: =SUMIFS(JU!$H$5107:$H$5107,JU!$F$5107:$F$5107,WS!$A19) -> 0 | AF19: =SUMIFS(JU!$K$5107:$K$5107,JU!$I$5107:$I$5107,WS!$A19) -> 0 | AH19: =SUMIFS(JU!$H$5107:$H$5107,JU!$F$5107:$F$5107,WS!$A19) -> 0 | AI19: =SUMIFS(JU!$K$5107:$K$5107,JU!$I$5107:$I$5107,WS!$A19) -> 0 | AK19: =SUMIFS(JU!$H$5107:$H$5107,JU!$F$5107:$F$5107,WS!$A19) -> 0 | AL19: =SUMIFS(JU!$K$5107:$K$5107,JU!$I$5107:$I$5107,WS!$A19) -> 0
A20: 1201 | B20: Deposito Jangka Pendek | C20: 0 | D20: =SUMIFS(JU!$H$5:$H$178,JU!$F$5:$F$178,WS!$A20) -> 0 | E20: =SUMIFS(JU!$K$5:$K$178,JU!$I$5:$I$178,WS!$A20) -> 0 | F20: =C20+D20-E20 -> 0 | G20: =SUMIFS(JU!$H$180:$H$440,JU!$F$180:$F$440,WS!$A20) -> 0 | H20: =SUMIFS(JU!$K$180:$K$440,JU!$I$180:$I$440,WS!$A20) -> 0 | I20: =F20+G20-H20 -> 0 | J20: =SUMIFS(JU!$H$441:$H$695,JU!$F$441:$F$695,WS!$A20) -> 0 | K20: =SUMIFS(JU!$K$441:$K$695,JU!$I$441:$I$695,WS!$A20) -> 0 | L20: =I20+J20-K20 -> 0 | M20: =SUMIFS(JU!$H$696:$H$1062,JU!$F$696:$F$1062,$A20) -> 0 | N20: =SUMIFS(JU!$K$696:$K$1062,JU!$I$696:$I$1062,WS!$A20) -> 0 | O20: =L20+M20-N20 -> 0 | P20: =SUMIFS(JU!$H$1063:$H$5007,JU!$F$1063:$F$5007,WS!$A20) -> 0 | Q20: =SUMIFS(JU!$K$1063:$K$5007,JU!$I$1063:$I$5007,WS!$A20) -> 0 | R20: =O20+P20-Q20 -> 0 | S20: =SUMIFS(JU!$H$5107:$H$5107,JU!$F$5107:$F$5107,WS!$A20) -> 0 | T20: =SUMIFS(JU!$K$5107:$K$5107,JU!$I$5107:$I$5107,WS!$A20) -> 0 | U20: =R20+S20-T20 -> 0 | V20: =SUMIFS(JU!$H$5107:$H$5107,JU!$F$5107:$F$5107,WS!$A20) -> 0 | W20: =SUMIFS(JU!$K$5107:$K$5107,JU!$I$5107:$I$5107,WS!$A20) -> 0 | X20: =U20+V20-W20 -> 0 | Y20: =SUMIFS(JU!$H$5107:$H$5107,JU!$F$5107:$F$5107,WS!$A20) -> 0 | Z20: =SUMIFS(JU!$K$5107:$K$5107,JU!$I$5107:$I$5107,WS!$A20) -> 0 | AA20: =X20+Y20-Z20 -> 0 | AB20: =SUMIFS(JU!$H$5107:$H$5107,JU!$F$5107:$F$5107,WS!$A20) -> 0 | AC20: =SUMIFS(JU!$K$5107:$K$5107,JU!$I$5107:$I$5107,WS!$A20) -> 0 | AD20: =AA20+AB20-AC20 -> 0 | AE20: =SUMIFS(JU!$H$5107:$H$5107,JU!$F$5107:$F$5107,WS!$A20) -> 0 | AF20: =SUMIFS(JU!$K$5107:$K$5107,JU!$I$5107:$I$5107,WS!$A20) -> 0 | AG20: =AD20+AE20-AF20 -> 0 | AH20: =SUMIFS(JU!$H$5107:$H$5107,JU!$F$5107:$F$5107,WS!$A20) -> 0 | AI20: =SUMIFS(JU!$K$5107:$K$5107,JU!$I$5107:$I$5107,WS!$A20) -> 0 | AJ20: =AG20+AH20-AI20 -> 0 | AK20: =SUMIFS(JU!$H$5107:$H$5107,JU!$F$5107:$F$5107,WS!$A20) -> 0 | AL20: =SUMIFS(JU!$K$5107:$K$5107,JU!$I$5107:$I$5107,WS!$A20) -> 0 | AM20: =AJ20+AK20-AL20 -> 0
A21: 1202 | B21: Piutang Usaha | C21: 1410490000 | D21: =SUMIFS(JU!$H$5:$H$178,JU!$F$5:$F$178,WS!$A21) -> 138000000 | E21: =SUMIFS(JU!$K$5:$K$178,JU!$I$5:$I$178,WS!$A21) -> 507350000 | F21: =C21+D21-E21 -> 1041140000 | G21: =SUMIFS(JU!$H$180:$H$440,JU!$F$180:$F$440,WS!$A21) -> 507000000 | H21: =SUMIFS(JU!$K$180:$K$440,JU!$I$180:$I$440,WS!$A21) -> 734679346 | I21: =F21+G21-H21 -> 813460654 | J21: =SUMIFS(JU!$H$441:$H$695,JU!$F$441:$F$695,WS!$A21) -> 522000000 | K21: =SUMIFS(JU!$K$441:$K$695,JU!$I$441:$I$695,WS!$A21) -> 624000000 | L21: =I21+J21-K21 -> 711460654 | M21: =SUMIFS(JU!$H$696:$H$1062,JU!$F$696:$F$1062,$A21) -> 2030610000 | N21: =SUMIFS(JU!$K$696:$K$1062,JU!$I$696:$I$1062,WS!$A21) -> 1359500000 | O21: =L21+M21-N21 -> 1382570654 | P21: =SUMIFS(JU!$H$1063:$H$5007,JU!$F$1063:$F$5007,WS!$A21) -> 2102744000 | Q21: =SUMIFS(JU!$K$1063:$K$5007,JU!$I$1063:$I$5007,WS!$A21) -> 1180990000 | R21: =O21+P21-Q21 -> 2304324654 | S21: =SUMIFS(JU!$H$5107:$H$5107,JU!$F$5107:$F$5107,WS!$A21) -> 0 | T21: =SUMIFS(JU!$K$5107:$K$5107,JU!$I$5107:$I$5107,WS!$A21) -> 0 | U21: =R21+S21-T21 -> 2304324654 | V21: =SUMIFS(JU!$H$5107:$H$5107,JU!$F$5107:$F$5107,WS!$A21) -> 0 | W21: =SUMIFS(JU!$K$5107:$K$5107,JU!$I$5107:$I$5107,WS!$A21) -> 0 | X21: =U21+V21-W21 -> 2304324654 | Y21: =SUMIFS(JU!$H$5107:$H$5107,JU!$F$5107:$F$5107,WS!$A21) -> 0 | Z21: =SUMIFS(JU!$K$5107:$K$5107,JU!$I$5107:$I$5107,WS!$A21) -> 0 | AA21: =X21+Y21-Z21 -> 2304324654 | AB21: =SUMIFS(JU!$H$5107:$H$5107,JU!$F$5107:$F$5107,WS!$A21) -> 0 | AC21: =SUMIFS(JU!$K$5107:$K$5107,JU!$I$5107:$I$5107,WS!$A21) -> 0 | AD21: =AA21+AB21-AC21 -> 2304324654 | AE21: =SUMIFS(JU!$H$5107:$H$5107,JU!$F$5107:$F$5107,WS!$A21) -> 0 | AF21: =SUMIFS(JU!$K$5107:$K$5107,JU!$I$5107:$I$5107,WS!$A21) -> 0 | AG21: =AD21+AE21-AF21 -> 2304324654 | AH21: =SUMIFS(JU!$H$5107:$H$5107,JU!$F$5107:$F$5107,WS!$A21) -> 0 | AI21: =SUMIFS(JU!$K$5107:$K$5107,JU!$I$5107:$I$5107,WS!$A21) -> 0 | AJ21: =AG21+AH21-AI21 -> 2304324654 | AK21: =SUMIFS(JU!$H$5107:$H$5107,JU!$F$5107:$F$5107,WS!$A21) -> 0 | AL21: =SUMIFS(JU!$K$5107:$K$5107,JU!$I$5107:$I$5107,WS!$A21) -> 0 | AM21: =AJ21+AK21-AL21 -> 2304324654
A22: 1203 | B22: Piutang Afiliasi | C22: 352700000 | D22: =SUMIFS(JU!$H$5:$H$178,JU!$F$5:$F$178,WS!$A22) -> 159987500 | E22: =SUMIFS(JU!$K$5:$K$178,JU!$I$5:$I$178,WS!$A22) -> 177487500 | F22: =C22+D22-E22 -> 335200000 | G22: =SUMIFS(JU!$H$180:$H$440,JU!$F$180:$F$440,WS!$A22) -> 201800000 | H22: =SUMIFS(JU!$K$180:$K$440,JU!$I$180:$I$440,WS!$A22) -> 26800000 | I22: =F22+G22-H22 -> 510200000 | J22: =SUMIFS(JU!$H$441:$H$695,JU!$F$441:$F$695,WS!$A22) -> 170250000 | K22: =SUMIFS(JU!$K$441:$K$695,JU!$I$441:$I$695,WS!$A22) -> 77000000 | L22: =I22+J22-K22 -> 603450000 | M22: =SUMIFS(JU!$H$696:$H$1062,JU!$F$696:$F$1062,$A22) -> 405865000 | N22: =SUMIFS(JU!$K$696:$K$1062,JU!$I$696:$I$1062,WS!$A22) -> 299500000 | O22: =L22+M22-N22 -> 709815000 | P22: =SUMIFS(JU!$H$1063:$H$5007,JU!$F$1063:$F$5007,WS!$A22) -> 810942000 | Q22: =SUMIFS(JU!$K$1063:$K$5007,JU!$I$1063:$I$5007,WS!$A22) -> 66000000 | R22: =O22+P22-Q22 -> 1454757000 | S22: =SUMIFS(JU!$H$5107:$H$5107,JU!$F$5107:$F$5107,WS!$A22) -> 0 | T22: =SUMIFS(JU!$K$5107:$K$5107,JU!$I$5107:$I$5107,WS!$A22) -> 0 | U22: =R22+S22-T22 -> 1454757000 | V22: =SUMIFS(JU!$H$5107:$H$5107,JU!$F$5107:$F$5107,WS!$A22) -> 0 | W22: =SUMIFS(JU!$K$5107:$K$5107,JU!$I$5107:$I$5107,WS!$A22) -> 0 | X22: =U22+V22-W22 -> 1454757000 | Y22: =SUMIFS(JU!$H$5107:$H$5107,JU!$F$5107:$F$5107,WS!$A22) -> 0 | Z22: =SUMIFS(JU!$K$5107:$K$5107,JU!$I$5107:$I$5107,WS!$A22) -> 0 | AA22: =X22+Y22-Z22 -> 1454757000 | AB22: =SUMIFS(JU!$H$5107:$H$5107,JU!$F$5107:$F$5107,WS!$A22) -> 0 | AC22: =SUMIFS(JU!$K$5107:$K$5107,JU!$I$5107:$I$5107,WS!$A22) -> 0 | AD22: =AA22+AB22-AC22 -> 1454757000 | AE22: =SUMIFS(JU!$H$5107:$H$5107,JU!$F$5107:$F$5107,WS!$A22) -> 0 | AF22: =SUMIFS(JU!$K$5107:$K$5107,JU!$I$5107:$I$5107,WS!$A22) -> 0 | AG22: =AD22+AE22-AF22 -> 1454757000 | AH22: =SUMIFS(JU!$H$5107:$H$5107,JU!$F$5107:$F$5107,WS!$A22) -> 0 | AI22: =SUMIFS(JU!$K$5107:$K$5107,JU!$I$5107:$I$5107,WS!$A22) -> 0 | AJ22: =AG22+AH22-AI22 -> 1454757000 | AK22: =SUMIFS(JU!$H$5107:$H$5107,JU!$F$5107:$F$5107,WS!$A22) -> 0 | AL22: =SUMIFS(JU!$K$5107:$K$5107,JU!$I$5107:$I$5107,WS!$A22) -> 0 | AM22: =AJ22+AK22-AL22 -> 1454757000
A23: 1204 | B23: Piutang Lain-lain | C23: 99500000 | D23: =SUMIFS(JU!$H$5:$H$178,JU!$F$5:$F$178,WS!$A23) -> 25000000 | E23: =SUMIFS(JU!$K$5:$K$178,JU!$I$5:$I$178,WS!$A23) -> 52500000 | F23: =C23+D23-E23 -> 72000000 | G23: =SUMIFS(JU!$H$180:$H$440,JU!$F$180:$F$440,WS!$A23) -> 10000000 | H23: =SUMIFS(JU!$K$180:$K$440,JU!$I$180:$I$440,WS!$A23) -> 0 | I23: =F23+G23-H23 -> 82000000 | J23: =SUMIFS(JU!$H$441:$H$695,JU!$F$441:$F$695,WS!$A23) -> 15000000 | K23: =SUMIFS(JU!$K$441:$K$695,JU!$I$441:$I$695,WS!$A23) -> 15000000 | L23: =I23+J23-K23 -> 82000000 | M23: =SUMIFS(JU!$H$696:$H$1062,JU!$F$696:$F$1062,$A23) -> 3040000 | N23: =SUMIFS(JU!$K$696:$K$1062,JU!$I$696:$I$1062,WS!$A23) -> 10000000 | O23: =L23+M23-N23 -> 75040000 | P23: =SUMIFS(JU!$H$1063:$H$5007,JU!$F$1063:$F$5007,WS!$A23) -> 0 | Q23: =SUMIFS(JU!$K$1063:$K$5007,JU!$I$1063:$I$5007,WS!$A23) -> 0 | R23: =O23+P23-Q23 -> 75040000 | S23: =SUMIFS(JU!$H$5107:$H$5107,JU!$F$5107:$F$5107,WS!$A23) -> 0 | T23: =SUMIFS(JU!$K$5107:$K$5107,JU!$I$5107:$I$5107,WS!$A23) -> 0 | U23: =R23+S23-T23 -> 75040000 | V23: =SUMIFS(JU!$H$5107:$H$5107,JU!$F$5107:$F$5107,WS!$A23) -> 0 | W23: =SUMIFS(JU!$K$5107:$K$5107,JU!$I$5107:$I$5107,WS!$A23) -> 0 | X23: =U23+V23-W23 -> 75040000 | Y23: =SUMIFS(JU!$H$5107:$H$5107,JU!$F$5107:$F$5107,WS!$A23) -> 0 | Z23: =SUMIFS(JU!$K$5107:$K$5107,JU!$I$5107:$I$5107,WS!$A23) -> 0 | AA23: =X23+Y23-Z23 -> 75040000 | AB23: =SUMIFS(JU!$H$5107:$H$5107,JU!$F$5107:$F$5107,WS!$A23) -> 0 | AC23: =SUMIFS(JU!$K$5107:$K$5107,JU!$I$5107:$I$5107,WS!$A23) -> 0 | AD23: =AA23+AB23-AC23 -> 75040000 | AE23: =SUMIFS(JU!$H$5107:$H$5107,JU!$F$5107:$F$5107,WS!$A23) -> 0 | AF23: =SUMIFS(JU!$K$5107:$K$5107,JU!$I$5107:$I$5107,WS!$A23) -> 0 | AG23: =AD23+AE23-AF23 -> 75040000 | AH23: =SUMIFS(JU!$H$5107:$H$5107,JU!$F$5107:$F$5107,WS!$A23) -> 0 | AI23: =SUMIFS(JU!$K$5107:$K$5107,JU!$I$5107:$I$5107,WS!$A23) -> 0 | AJ23: =AG23+AH23-AI23 -> 75040000 | AK23: =SUMIFS(JU!$H$5107:$H$5107,JU!$F$5107:$F$5107,WS!$A23) -> 0 | AL23: =SUMIFS(JU!$K$5107:$K$5107,JU!$I$5107:$I$5107,WS!$A23) -> 0 | AM23: =AJ23+AK23-AL23 -> 75040000
A24: 1205 | B24: Uang Muka Pembelian Tanah | C24: 0 | D24: =SUMIFS(JU!$H$5:$H$178,JU!$F$5:$F$178,WS!$A24) -> 0 | E24: =SUMIFS(JU!$K$5:$K$178,JU!$I$5:$I$178,WS!$A24) -> 0 | F24: =C24+D24-E24 -> 0 | G24: =SUMIFS(JU!$H$180:$H$440,JU!$F$180:$F$440,WS!$A24) -> 0 | H24: =SUMIFS(JU!$K$180:$K$440,JU!$I$180:$I$440,WS!$A24) -> 0 | I24: =F24+G24-H24 -> 0 | J24: =SUMIFS(JU!$H$441:$H$695,JU!$F$441:$F$695,WS!$A24) -> 0 | K24: =SUMIFS(JU!$K$441:$K$695,JU!$I$441:$I$695,WS!$A24) -> 0 | L24: =I24+J24-K24 -> 0 | M24: =SUMIFS(JU!$H$696:$H$1062,JU!$F$696:$F$1062,$A24) -> 0 | N24: =SUMIFS(JU!$K$696:$K$1062,JU!$I$696:$I$1062,WS!$A24) -> 0 | O24: =L24+M24-N24 -> 0 | P24: =SUMIFS(JU!$H$1063:$H$5007,JU!$F$1063:$F$5007,WS!$A24) -> 0 | Q24: =SUMIFS(JU!$K$1063:$K$5007,JU!$I$1063:$I$5007,WS!$A24) -> 0 | R24: =O24+P24-Q24 -> 0 | S24: =SUMIFS(JU!$H$5107:$H$5107,JU!$F$5107:$F$5107,WS!$A24) -> 0 | T24: =SUMIFS(JU!$K$5107:$K$5107,JU!$I$5107:$I$5107,WS!$A24) -> 0 | U24: =R24+S24-T24 -> 0 | V24: =SUMIFS(JU!$H$5107:$H$5107,JU!$F$5107:$F$5107,WS!$A24) -> 0 | W24: =SUMIFS(JU!$K$5107:$K$5107,JU!$I$5107:$I$5107,WS!$A24) -> 0 | X24: =U24+V24-W24 -> 0 | Y24: =SUMIFS(JU!$H$5107:$H$5107,JU!$F$5107:$F$5107,WS!$A24) -> 0 | Z24: =SUMIFS(JU!$K$5107:$K$5107,JU!$I$5107:$I$5107,WS!$A24) -> 0 | AA24: =X24+Y24-Z24 -> 0 | AB24: =SUMIFS(JU!$H$5107:$H$5107,JU!$F$5107:$F$5107,WS!$A24) -> 0 | AC24: =SUMIFS(JU!$K$5107:$K$5107,JU!$I$5107:$I$5107,WS!$A24) -> 0 | AD24: =AA24+AB24-AC24 -> 0 | AE24: =SUMIFS(JU!$H$5107:$H$5107,JU!$F$5107:$F$5107,WS!$A24) -> 0 | AF24: =SUMIFS(JU!$K$5107:$K$5107,JU!$I$5107:$I$5107,WS!$A24) -> 0 | AG24: =AD24+AE24-AF24 -> 0 | AH24: =SUMIFS(JU!$H$5107:$H$5107,JU!$F$5107:$F$5107,WS!$A24) -> 0 | AI24: =SUMIFS(JU!$K$5107:$K$5107,JU!$I$5107:$I$5107,WS!$A24) -> 0 | AJ24: =AG24+AH24-AI24 -> 0 | AK24: =SUMIFS(JU!$H$5107:$H$5107,JU!$F$5107:$F$5107,WS!$A24) -> 0 | AL24: =SUMIFS(JU!$K$5107:$K$5107,JU!$I$5107:$I$5107,WS!$A24) -> 0 | AM24: =AJ24+AK24-AL24 -> 0
A25: 1206 | B25: Uang Muka Pembelian Konveksi | C25: 0 | D25: =SUMIFS(JU!$H$5:$H$178,JU!$F$5:$F$178,WS!$A25) -> 0 | E25: =SUMIFS(JU!$K$5:$K$178,JU!$I$5:$I$178,WS!$A25) -> 0 | F25: =C25+D25-E25 -> 0 | G25: =SUMIFS(JU!$H$180:$H$440,JU!$F$180:$F$440,WS!$A25) -> 0 | H25: =SUMIFS(JU!$K$180:$K$440,JU!$I$180:$I$440,WS!$A25) -> 0 | I25: =F25+G25-H25 -> 0 | J25: =SUMIFS(JU!$H$441:$H$695,JU!$F$441:$F$695,WS!$A25) -> 0 | K25: =SUMIFS(JU!$K$441:$K$695,JU!$I$441:$I$695,WS!$A25) -> 0 | L25: =I25+J25-K25 -> 0 | M25: =SUMIFS(JU!$H$696:$H$1062,JU!$F$696:$F$1062,$A25) -> 0 | N25: =SUMIFS(JU!$K$696:$K$1062,JU!$I$696:$I$1062,WS!$A25) -> 0 | O25: =L25+M25-N25 -> 0 | P25: =SUMIFS(JU!$H$1063:$H$5007,JU!$F$1063:$F$5007,WS!$A25) -> 0 | Q25: =SUMIFS(JU!$K$1063:$K$5007,JU!$I$1063:$I$5007,WS!$A25) -> 0 | R25: =O25+P25-Q25 -> 0 | S25: =SUMIFS(JU!$H$5107:$H$5107,JU!$F$5107:$F$5107,WS!$A25) -> 0 | T25: =SUMIFS(JU!$K$5107:$K$5107,JU!$I$5107:$I$5107,WS!$A25) -> 0 | U25: =R25+S25-T25 -> 0 | V25: =SUMIFS(JU!$H$5107:$H$5107,JU!$F$5107:$F$5107,WS!$A25) -> 0 | W25: =SUMIFS(JU!$K$5107:$K$5107,JU!$I$5107:$I$5107,WS!$A25) -> 0 | X25: =U25+V25-W25 -> 0 | Y25: =SUMIFS(JU!$H$5107:$H$5107,JU!$F$5107:$F$5107,WS!$A25) -> 0 | Z25: =SUMIFS(JU!$K$5107:$K$5107,JU!$I$5107:$I$5107,WS!$A25) -> 0 | AA25: =X25+Y25-Z25 -> 0 | AB25: =SUMIFS(JU!$H$5107:$H$5107,JU!$F$5107:$F$5107,WS!$A25) -> 0 | AC25: =SUMIFS(JU!$K$5107:$K$5107,JU!$I$5107:$I$5107,WS!$A25) -> 0 | AD25: =AA25+AB25-AC25 -> 0 | AE25: =SUMIFS(JU!$H$5107:$H$5107,JU!$F$5107:$F$5107,WS!$A25) -> 0 | AF25: =SUMIFS(JU!$K$5107:$K$5107,JU!$I$5107:$I$5107,WS!$A25) -> 0 | AG25: =AD25+AE25-AF25 -> 0 | AH25: =SUMIFS(JU!$H$5107:$H$5107,JU!$F$5107:$F$5107,WS!$A25) -> 0 | AI25: =SUMIFS(JU!$K$5107:$K$5107,JU!$I$5107:$I$5107,WS!$A25) -> 0 | AJ25: =AG25+AH25-AI25 -> 0 | AK25: =SUMIFS(JU!$H$5107:$H$5107,JU!$F$5107:$F$5107,WS!$A25) -> 0 | AL25: =SUMIFS(JU!$K$5107:$K$5107,JU!$I$5107:$I$5107,WS!$A25) -> 0 | AM25: =AJ25+AK25-AL25 -> 0
A26: 1207 | B26: Pajak Dibayar di Muka | C26: 0 | D26: =SUMIFS(JU!$H$5:$H$178,JU!$F$5:$F$178,WS!$A26) -> 0 | E26: =SUMIFS(JU!$K$5:$K$178,JU!$I$5:$I$178,WS!$A26) -> 0 | F26: =C26+D26-E26 -> 0 | G26: =SUMIFS(JU!$H$180:$H$440,JU!$F$180:$F$440,WS!$A26) -> 0 | H26: =SUMIFS(JU!$K$180:$K$440,JU!$I$180:$I$440,WS!$A26) -> 0 | I26: =F26+G26-H26 -> 0 | J26: =SUMIFS(JU!$H$441:$H$695,JU!$F$441:$F$695,WS!$A26) -> 0 | K26: =SUMIFS(JU!$K$441:$K$695,JU!$I$441:$I$695,WS!$A26) -> 0 | L26: =I26+J26-K26 -> 0 | M26: =SUMIFS(JU!$H$696:$H$1062,JU!$F$696:$F$1062,$A26) -> 0 | N26: =SUMIFS(JU!$K$696:$K$1062,JU!$I$696:$I$1062,WS!$A26) -> 0 | O26: =L26+M26-N26 -> 0 | P26: =SUMIFS(JU!$H$1063:$H$5007,JU!$F$1063:$F$5007,WS!$A26) -> 0 | Q26: =SUMIFS(JU!$K$1063:$K$5007,JU!$I$1063:$I$5007,WS!$A26) -> 0 | R26: =O26+P26-Q26 -> 0 | S26: =SUMIFS(JU!$H$5107:$H$5107,JU!$F$5107:$F$5107,WS!$A26) -> 0 | T26: =SUMIFS(JU!$K$5107:$K$5107,JU!$I$5107:$I$5107,WS!$A26) -> 0 | U26: =R26+S26-T26 -> 0 | V26: =SUMIFS(JU!$H$5107:$H$5107,JU!$F$5107:$F$5107,WS!$A26) -> 0 | W26: =SUMIFS(JU!$K$5107:$K$5107,JU!$I$5107:$I$5107,WS!$A26) -> 0 | X26: =U26+V26-W26 -> 0 | Y26: =SUMIFS(JU!$H$5107:$H$5107,JU!$F$5107:$F$5107,WS!$A26) -> 0 | Z26: =SUMIFS(JU!$K$5107:$K$5107,JU!$I$5107:$I$5107,WS!$A26) -> 0 | AA26: =X26+Y26-Z26 -> 0 | AB26: =SUMIFS(JU!$H$5107:$H$5107,JU!$F$5107:$F$5107,WS!$A26) -> 0 | AC26: =SUMIFS(JU!$K$5107:$K$5107,JU!$I$5107:$I$5107,WS!$A26) -> 0 | AD26: =AA26+AB26-AC26 -> 0 | AE26: =SUMIFS(JU!$H$5107:$H$5107,JU!$F$5107:$F$5107,WS!$A26) -> 0 | AF26: =SUMIFS(JU!$K$5107:$K$5107,JU!$I$5107:$I$5107,WS!$A26) -> 0 | AG26: =AD26+AE26-AF26 -> 0 | AH26: =SUMIFS(JU!$H$5107:$H$5107,JU!$F$5107:$F$5107,WS!$A26) -> 0 | AI26: =SUMIFS(JU!$K$5107:$K$5107,JU!$I$5107:$I$5107,WS!$A26) -> 0 | AJ26: =AG26+AH26-AI26 -> 0 | AK26: =SUMIFS(JU!$H$5107:$H$5107,JU!$F$5107:$F$5107,WS!$A26) -> 0 | AL26: =SUMIFS(JU!$K$5107:$K$5107,JU!$I$5107:$I$5107,WS!$A26) -> 0 | AM26: =AJ26+AK26-AL26 -> 0
A27: 1208 | B27: Biaya Dibayar di Muka | C27: 0 | D27: =SUMIFS(JU!$H$5:$H$178,JU!$F$5:$F$178,WS!$A27) -> 0 | E27: =SUMIFS(JU!$K$5:$K$178,JU!$I$5:$I$178,WS!$A27) -> 0 | F27: =C27+D27-E27 -> 0 | G27: =SUMIFS(JU!$H$180:$H$440,JU!$F$180:$F$440,WS!$A27) -> 0 | H27: =SUMIFS(JU!$K$180:$K$440,JU!$I$180:$I$440,WS!$A27) -> 0 | I27: =F27+G27-H27 -> 0 | J27: =SUMIFS(JU!$H$441:$H$695,JU!$F$441:$F$695,WS!$A27) -> 0 | K27: =SUMIFS(JU!$K$441:$K$695,JU!$I$441:$I$695,WS!$A27) -> 0 | L27: =I27+J27-K27 -> 0 | M27: =SUMIFS(JU!$H$696:$H$1062,JU!$F$696:$F$1062,$A27) -> 62500000 | N27: =SUMIFS(JU!$K$696:$K$1062,JU!$I$696:$I$1062,WS!$A27) -> 0 | O27: =L27+M27-N27 -> 62500000 | P27: =SUMIFS(JU!$H$1063:$H$5007,JU!$F$1063:$F$5007,WS!$A27) -> 0 | Q27: =SUMIFS(JU!$K$1063:$K$5007,JU!$I$1063:$I$5007,WS!$A27) -> 0 | R27: =O27+P27-Q27 -> 62500000 | S27: =SUMIFS(JU!$H$5107:$H$5107,JU!$F$5107:$F$5107,WS!$A27) -> 0 | T27: =SUMIFS(JU!$K$5107:$K$5107,JU!$I$5107:$I$5107,WS!$A27) -> 0 | U27: =R27+S27-T27 -> 62500000 | V27: =SUMIFS(JU!$H$5107:$H$5107,JU!$F$5107:$F$5107,WS!$A27) -> 0 | W27: =SUMIFS(JU!$K$5107:$K$5107,JU!$I$5107:$I$5107,WS!$A27) -> 0 | X27: =U27+V27-W27 -> 62500000 | Y27: =SUMIFS(JU!$H$5107:$H$5107,JU!$F$5107:$F$5107,WS!$A27) -> 0 | Z27: =SUMIFS(JU!$K$5107:$K$5107,JU!$I$5107:$I$5107,WS!$A27) -> 0 | AA27: =X27+Y27-Z27 -> 62500000 | AB27: =SUMIFS(JU!$H$5107:$H$5107,JU!$F$5107:$F$5107,WS!$A27) -> 0 | AC27: =SUMIFS(JU!$K$5107:$K$5107,JU!$I$5107:$I$5107,WS!$A27) -> 0 | AD27: =AA27+AB27-AC27 -> 62500000 | AE27: =SUMIFS(JU!$H$5107:$H$5107,JU!$F$5107:$F$5107,WS!$A27) -> 0 | AF27: =SUMIFS(JU!$K$5107:$K$5107,JU!$I$5107:$I$5107,WS!$A27) -> 0 | AG27: =AD27+AE27-AF27 -> 62500000 | AH27: =SUMIFS(JU!$H$5107:$H$5107,JU!$F$5107:$F$5107,WS!$A27) -> 0 | AI27: =SUMIFS(JU!$K$5107:$K$5107,JU!$I$5107:$I$5107,WS!$A27) -> 0 | AJ27: =AG27+AH27-AI27 -> 62500000 | AK27: =SUMIFS(JU!$H$5107:$H$5107,JU!$F$5107:$F$5107,WS!$A27) -> 0 | AL27: =SUMIFS(JU!$K$5107:$K$5107,JU!$I$5107:$I$5107,WS!$A27) -> 0 | AM27: =AJ27+AK27-AL27 -> 62500000
A28: Total Piutang | C28: 1862690000 | D28: =SUMIFS(JU!$H$5:$H$178,JU!$F$5:$F$178,WS!$A28) -> 0 | E28: =SUMIFS(JU!$K$5:$K$178,JU!$I$5:$I$178,WS!$A28) -> 0 | F28: =SUM(F20:F27) -> 1448340000 | G28: =SUMIFS(JU!$H$180:$H$440,JU!$F$180:$F$440,WS!$A28) -> 0 | H28: =SUMIFS(JU!$K$180:$K$440,JU!$I$180:$I$440,WS!$A28) -> 0 | I28: =SUM(I20:I27) -> 1405660654 | J28: =SUMIFS(JU!$H$441:$H$695,JU!$F$441:$F$695,WS!$A28) -> 0 | K28: =SUMIFS(JU!$K$441:$K$695,JU!$I$441:$I$695,WS!$A28) -> 0 | L28: =SUM(L20:L27) -> 1396910654 | M28: =SUMIFS(JU!$H$696:$H$1062,JU!$F$696:$F$1062,$A28) -> 0 | N28: =SUMIFS(JU!$K$696:$K$1062,JU!$I$696:$I$1062,WS!$A28) -> 0 | O28: =SUM(O20:O27) -> 2229925654 | P28: =SUMIFS(JU!$H$1063:$H$5007,JU!$F$1063:$F$5007,WS!$A28) -> 0 | Q28: =SUMIFS(JU!$K$1063:$K$5007,JU!$I$1063:$I$5007,WS!$A28) -> 0 | R28: =SUM(R20:R27) -> 3896621654 | S28: =SUMIFS(JU!$H$5107:$H$5107,JU!$F$5107:$F$5107,WS!$A28) -> 0 | T28: =SUMIFS(JU!$K$5107:$K$5107,JU!$I$5107:$I$5107,WS!$A28) -> 0 | U28: =SUM(U20:U27) -> 3896621654 | V28: =SUMIFS(JU!$H$5107:$H$5107,JU!$F$5107:$F$5107,WS!$A28) -> 0 | W28: =SUMIFS(JU!$K$5107:$K$5107,JU!$I$5107:$I$5107,WS!$A28) -> 0 | X28: =SUM(X20:X27) -> 3896621654 | Y28: =SUMIFS(JU!$H$5107:$H$5107,JU!$F$5107:$F$5107,WS!$A28) -> 0 | Z28: =SUMIFS(JU!$K$5107:$K$5107,JU!$I$5107:$I$5107,WS!$A28) -> 0 | AA28: =SUM(AA20:AA27) -> 3896621654 | AB28: =SUMIFS(JU!$H$5107:$H$5107,JU!$F$5107:$F$5107,WS!$A28) -> 0 | AC28: =SUMIFS(JU!$K$5107:$K$5107,JU!$I$5107:$I$5107,WS!$A28) -> 0 | AD28: =SUM(AD20:AD27) -> 3896621654 | AE28: =SUMIFS(JU!$H$5107:$H$5107,JU!$F$5107:$F$5107,WS!$A28) -> 0 | AF28: =SUMIFS(JU!$K$5107:$K$5107,JU!$I$5107:$I$5107,WS!$A28) -> 0 | AG28: =SUM(AG20:AG27) -> 3896621654 | AH28: =SUMIFS(JU!$H$5107:$H$5107,JU!$F$5107:$F$5107,WS!$A28) -> 0 | AI28: =SUMIFS(JU!$K$5107:$K$5107,JU!$I$5107:$I$5107,WS!$A28) -> 0 | AJ28: =SUM(AJ20:AJ27) -> 3896621654 | AK28: =SUMIFS(JU!$H$5107:$H$5107,JU!$F$5107:$F$5107,WS!$A28) -> 0 | AL28: =SUMIFS(JU!$K$5107:$K$5107,JU!$I$5107:$I$5107,WS!$A28) -> 0 | AM28: =SUM(AM20:AM27) -> 3896621654
A29: Persediaan | D29: =SUMIFS(JU!$H$5:$H$178,JU!$F$5:$F$178,WS!$A29) -> 0 | E29: =SUMIFS(JU!$K$5:$K$178,JU!$I$5:$I$178,WS!$A29) -> 0 | G29: =SUMIFS(JU!$H$180:$H$440,JU!$F$180:$F$440,WS!$A29) -> 0 | H29: =SUMIFS(JU!$K$180:$K$440,JU!$I$180:$I$440,WS!$A29) -> 0 | J29: =SUMIFS(JU!$H$441:$H$695,JU!$F$441:$F$695,WS!$A29) -> 0 | K29: =SUMIFS(JU!$K$441:$K$695,JU!$I$441:$I$695,WS!$A29) -> 0 | M29: =SUMIFS(JU!$H$696:$H$1062,JU!$F$696:$F$1062,$A29) -> 0 | N29: =SUMIFS(JU!$K$696:$K$1062,JU!$I$696:$I$1062,WS!$A29) -> 0 | P29: =SUMIFS(JU!$H$1063:$H$5007,JU!$F$1063:$F$5007,WS!$A29) -> 0 | Q29: =SUMIFS(JU!$K$1063:$K$5007,JU!$I$1063:$I$5007,WS!$A29) -> 0 | S29: =SUMIFS(JU!$H$5107:$H$5107,JU!$F$5107:$F$5107,WS!$A29) -> 0 | T29: =SUMIFS(JU!$K$5107:$K$5107,JU!$I$5107:$I$5107,WS!$A29) -> 0 | V29: =SUMIFS(JU!$H$5107:$H$5107,JU!$F$5107:$F$5107,WS!$A29) -> 0 | W29: =SUMIFS(JU!$K$5107:$K$5107,JU!$I$5107:$I$5107,WS!$A29) -> 0 | Y29: =SUMIFS(JU!$H$5107:$H$5107,JU!$F$5107:$F$5107,WS!$A29) -> 0 | Z29: =SUMIFS(JU!$K$5107:$K$5107,JU!$I$5107:$I$5107,WS!$A29) -> 0 | AB29: =SUMIFS(JU!$H$5107:$H$5107,JU!$F$5107:$F$5107,WS!$A29) -> 0 | AC29: =SUMIFS(JU!$K$5107:$K$5107,JU!$I$5107:$I$5107,WS!$A29) -> 0 | AE29: =SUMIFS(JU!$H$5107:$H$5107,JU!$F$5107:$F$5107,WS!$A29) -> 0 | AF29: =SUMIFS(JU!$K$5107:$K$5107,JU!$I$5107:$I$5107,WS!$A29) -> 0 | AH29: =SUMIFS(JU!$H$5107:$H$5107,JU!$F$5107:$F$5107,WS!$A29) -> 0 | AI29: =SUMIFS(JU!$K$5107:$K$5107,JU!$I$5107:$I$5107,WS!$A29) -> 0 | AK29: =SUMIFS(JU!$H$5107:$H$5107,JU!$F$5107:$F$5107,WS!$A29) -> 0 | AL29: =SUMIFS(JU!$K$5107:$K$5107,JU!$I$5107:$I$5107,WS!$A29) -> 0
A30: 1301 | B30: Persediaan Tanah dalam Pengembangan | C30: 1500000000 | D30: =SUMIFS(JU!$H$5:$H$178,JU!$F$5:$F$178,WS!$A30) -> 96523717 | E30: =SUMIFS(JU!$K$5:$K$178,JU!$I$5:$I$178,WS!$A30) -> 0 | F30: =C30+D30-E30 -> 1596523717 | G30: =SUMIFS(JU!$H$180:$H$440,JU!$F$180:$F$440,WS!$A30) -> 1074680000 | H30: =SUMIFS(JU!$K$180:$K$440,JU!$I$180:$I$440,WS!$A30) -> 0 | I30: =F30+G30-H30 -> 2671203717 | J30: =SUMIFS(JU!$H$441:$H$695,JU!$F$441:$F$695,WS!$A30) -> 1260750000 | K30: =SUMIFS(JU!$K$441:$K$695,JU!$I$441:$I$695,WS!$A30) -> 0 | L30: =I30+J30-K30 -> 3931953717 | M30: =SUMIFS(JU!$H$696:$H$1062,JU!$F$696:$F$1062,$A30) -> 75400000 | N30: =SUMIFS(JU!$K$696:$K$1062,JU!$I$696:$I$1062,WS!$A30) -> 0 | O30: =L30+M30-N30 -> 4007353717 | P30: =SUMIFS(JU!$H$1063:$H$5007,JU!$F$1063:$F$5007,WS!$A30) -> 601750000 | Q30: =SUMIFS(JU!$K$1063:$K$5007,JU!$I$1063:$I$5007,WS!$A30) -> 128000000 | R30: =O30+P30-Q30 -> 4481103717 | S30: =SUMIFS(JU!$H$5107:$H$5107,JU!$F$5107:$F$5107,WS!$A30) -> 0 | T30: =SUMIFS(JU!$K$5107:$K$5107,JU!$I$5107:$I$5107,WS!$A30) -> 0 | U30: =R30+S30-T30 -> 4481103717 | V30: =SUMIFS(JU!$H$5107:$H$5107,JU!$F$5107:$F$5107,WS!$A30) -> 0 | W30: =SUMIFS(JU!$K$5107:$K$5107,JU!$I$5107:$I$5107,WS!$A30) -> 0 | X30: =U30+V30-W30 -> 4481103717 | Y30: =SUMIFS(JU!$H$5107:$H$5107,JU!$F$5107:$F$5107,WS!$A30) -> 0 | Z30: =SUMIFS(JU!$K$5107:$K$5107,JU!$I$5107:$I$5107,WS!$A30) -> 0 | AA30: =X30+Y30-Z30 -> 4481103717 | AB30: =SUMIFS(JU!$H$5107:$H$5107,JU!$F$5107:$F$5107,WS!$A30) -> 0 | AC30: =SUMIFS(JU!$K$5107:$K$5107,JU!$I$5107:$I$5107,WS!$A30) -> 0 | AD30: =AA30+AB30-AC30 -> 4481103717 | AE30: =SUMIFS(JU!$H$5107:$H$5107,JU!$F$5107:$F$5107,WS!$A30) -> 0 | AF30: =SUMIFS(JU!$K$5107:$K$5107,JU!$I$5107:$I$5107,WS!$A30) -> 0 | AG30: =AD30+AE30-AF30 -> 4481103717 | AH30: =SUMIFS(JU!$H$5107:$H$5107,JU!$F$5107:$F$5107,WS!$A30) -> 0 | AI30: =SUMIFS(JU!$K$5107:$K$5107,JU!$I$5107:$I$5107,WS!$A30) -> 0 | AJ30: =AG30+AH30-AI30 -> 4481103717 | AK30: =SUMIFS(JU!$H$5107:$H$5107,JU!$F$5107:$F$5107,WS!$A30) -> 0 | AL30: =SUMIFS(JU!$K$5107:$K$5107,JU!$I$5107:$I$5107,WS!$A30) -> 0 | AM30: =AJ30+AK30-AL30 -> 4481103717
A31: 1302 | B31: Persediaan Bangunan dalam Proses | C31: 0 | D31: =SUMIFS(JU!$H$5:$H$178,JU!$F$5:$F$178,WS!$A31) -> 213804059 | E31: =SUMIFS(JU!$K$5:$K$178,JU!$I$5:$I$178,WS!$A31) -> 0 | F31: =C31+D31-E31 -> 213804059 | G31: =SUMIFS(JU!$H$180:$H$440,JU!$F$180:$F$440,WS!$A31) -> 484664450 | H31: =SUMIFS(JU!$K$180:$K$440,JU!$I$180:$I$440,WS!$A31) -> 195200000 | I31: =F31+G31-H31 -> 503268509 | J31: =SUMIFS(JU!$H$441:$H$695,JU!$F$441:$F$695,WS!$A31) -> 731465000 | K31: =SUMIFS(JU!$K$441:$K$695,JU!$I$441:$I$695,WS!$A31) -> 195000000 | L31: =I31+J31-K31 -> 1039733509 | M31: =SUMIFS(JU!$H$696:$H$1062,JU!$F$696:$F$1062,$A31) -> 618415100 | N31: =SUMIFS(JU!$K$696:$K$1062,JU!$I$696:$I$1062,WS!$A31) -> 780000000 | O31: =L31+M31-N31 -> 878148609 | P31: =SUMIFS(JU!$H$1063:$H$5007,JU!$F$1063:$F$5007,WS!$A31) -> 889295500 | Q31: =SUMIFS(JU!$K$1063:$K$5007,JU!$I$1063:$I$5007,WS!$A31) -> 863600000 | R31: =O31+P31-Q31 -> 903844109 | S31: =SUMIFS(JU!$H$5107:$H$5107,JU!$F$5107:$F$5107,WS!$A31) -> 0 | T31: =SUMIFS(JU!$K$5107:$K$5107,JU!$I$5107:$I$5107,WS!$A31) -> 0 | U31: =R31+S31-T31 -> 903844109 | V31: =SUMIFS(JU!$H$5107:$H$5107,JU!$F$5107:$F$5107,WS!$A31) -> 0 | W31: =SUMIFS(JU!$K$5107:$K$5107,JU!$I$5107:$I$5107,WS!$A31) -> 0 | X31: =U31+V31-W31 -> 903844109 | Y31: =SUMIFS(JU!$H$5107:$H$5107,JU!$F$5107:$F$5107,WS!$A31) -> 0 | Z31: =SUMIFS(JU!$K$5107:$K$5107,JU!$I$5107:$I$5107,WS!$A31) -> 0 | AA31: =X31+Y31-Z31 -> 903844109 | AB31: =SUMIFS(JU!$H$5107:$H$5107,JU!$F$5107:$F$5107,WS!$A31) -> 0 | AC31: =SUMIFS(JU!$K$5107:$K$5107,JU!$I$5107:$I$5107,WS!$A31) -> 0 | AD31: =AA31+AB31-AC31 -> 903844109 | AE31: =SUMIFS(JU!$H$5107:$H$5107,JU!$F$5107:$F$5107,WS!$A31) -> 0 | AF31: =SUMIFS(JU!$K$5107:$K$5107,JU!$I$5107:$I$5107,WS!$A31) -> 0 | AG31: =AD31+AE31-AF31 -> 903844109 | AH31: =SUMIFS(JU!$H$5107:$H$5107,JU!$F$5107:$F$5107,WS!$A31) -> 0 | AI31: =SUMIFS(JU!$K$5107:$K$5107,JU!$I$5107:$I$5107,WS!$A31) -> 0 | AJ31: =AG31+AH31-AI31 -> 903844109 | AK31: =SUMIFS(JU!$H$5107:$H$5107,JU!$F$5107:$F$5107,WS!$A31) -> 0 | AL31: =SUMIFS(JU!$K$5107:$K$5107,JU!$I$5107:$I$5107,WS!$A31) -> 0 | AM31: =AJ31+AK31-AL31 -> 903844109
A32: 1303 | B32: Persediaan Properti Siap Jual | C32: 1025000003 | D32: =SUMIFS(JU!$H$5:$H$178,JU!$F$5:$F$178,WS!$A32) -> 0 | E32: =SUMIFS(JU!$K$5:$K$178,JU!$I$5:$I$178,WS!$A32) -> 0 | F32: =C32+D32-E32 -> 1025000003 | G32: =SUMIFS(JU!$H$180:$H$440,JU!$F$180:$F$440,WS!$A32) -> 0 | H32: =SUMIFS(JU!$K$180:$K$440,JU!$I$180:$I$440,WS!$A32) -> 0 | I32: =F32+G32-H32 -> 1025000003 | J32: =SUMIFS(JU!$H$441:$H$695,JU!$F$441:$F$695,WS!$A32) -> 0 | K32: =SUMIFS(JU!$K$441:$K$695,JU!$I$441:$I$695,WS!$A32) -> 0 | L32: =I32+J32-K32 -> 1025000003 | M32: =SUMIFS(JU!$H$696:$H$1062,JU!$F$696:$F$1062,$A32) -> 0 | N32: =SUMIFS(JU!$K$696:$K$1062,JU!$I$696:$I$1062,WS!$A32) -> 0 | O32: =L32+M32-N32 -> 1025000003 | P32: =SUMIFS(JU!$H$1063:$H$5007,JU!$F$1063:$F$5007,WS!$A32) -> 0 | Q32: =SUMIFS(JU!$K$1063:$K$5007,JU!$I$1063:$I$5007,WS!$A32) -> 0 | R32: =O32+P32-Q32 -> 1025000003 | S32: =SUMIFS(JU!$H$5107:$H$5107,JU!$F$5107:$F$5107,WS!$A32) -> 0 | T32: =SUMIFS(JU!$K$5107:$K$5107,JU!$I$5107:$I$5107,WS!$A32) -> 0 | U32: =R32+S32-T32 -> 1025000003 | V32: =SUMIFS(JU!$H$5107:$H$5107,JU!$F$5107:$F$5107,WS!$A32) -> 0 | W32: =SUMIFS(JU!$K$5107:$K$5107,JU!$I$5107:$I$5107,WS!$A32) -> 0 | X32: =U32+V32-W32 -> 1025000003 | Y32: =SUMIFS(JU!$H$5107:$H$5107,JU!$F$5107:$F$5107,WS!$A32) -> 0 | Z32: =SUMIFS(JU!$K$5107:$K$5107,JU!$I$5107:$I$5107,WS!$A32) -> 0 | AA32: =X32+Y32-Z32 -> 1025000003 | AB32: =SUMIFS(JU!$H$5107:$H$5107,JU!$F$5107:$F$5107,WS!$A32) -> 0 | AC32: =SUMIFS(JU!$K$5107:$K$5107,JU!$I$5107:$I$5107,WS!$A32) -> 0 | AD32: =AA32+AB32-AC32 -> 1025000003 | AE32: =SUMIFS(JU!$H$5107:$H$5107,JU!$F$5107:$F$5107,WS!$A32) -> 0 | AF32: =SUMIFS(JU!$K$5107:$K$5107,JU!$I$5107:$I$5107,WS!$A32) -> 0 | AG32: =AD32+AE32-AF32 -> 1025000003 | AH32: =SUMIFS(JU!$H$5107:$H$5107,JU!$F$5107:$F$5107,WS!$A32) -> 0 | AI32: =SUMIFS(JU!$K$5107:$K$5107,JU!$I$5107:$I$5107,WS!$A32) -> 0 | AJ32: =AG32+AH32-AI32 -> 1025000003 | AK32: =SUMIFS(JU!$H$5107:$H$5107,JU!$F$5107:$F$5107,WS!$A32) -> 0 | AL32: =SUMIFS(JU!$K$5107:$K$5107,JU!$I$5107:$I$5107,WS!$A32) -> 0 | AM32: =AJ32+AK32-AL32 -> 1025000003
A33: 1304 | B33: Persediaan Bahan Baku | C33: 0 | D33: =SUMIFS(JU!$H$5:$H$178,JU!$F$5:$F$178,WS!$A33) -> 0 | E33: =SUMIFS(JU!$K$5:$K$178,JU!$I$5:$I$178,WS!$A33) -> 0 | F33: =C33+D33-E33 -> 0 | G33: =SUMIFS(JU!$H$180:$H$440,JU!$F$180:$F$440,WS!$A33) -> 0 | H33: =SUMIFS(JU!$K$180:$K$440,JU!$I$180:$I$440,WS!$A33) -> 0 | I33: =F33+G33-H33 -> 0 | J33: =SUMIFS(JU!$H$441:$H$695,JU!$F$441:$F$695,WS!$A33) -> 0 | K33: =SUMIFS(JU!$K$441:$K$695,JU!$I$441:$I$695,WS!$A33) -> 0 | L33: =I33+J33-K33 -> 0 | M33: =SUMIFS(JU!$H$696:$H$1062,JU!$F$696:$F$1062,$A33) -> 0 | N33: =SUMIFS(JU!$K$696:$K$1062,JU!$I$696:$I$1062,WS!$A33) -> 0 | O33: =L33+M33-N33 -> 0 | P33: =SUMIFS(JU!$H$1063:$H$5007,JU!$F$1063:$F$5007,WS!$A33) -> 0 | Q33: =SUMIFS(JU!$K$1063:$K$5007,JU!$I$1063:$I$5007,WS!$A33) -> 0 | R33: =O33+P33-Q33 -> 0 | S33: =SUMIFS(JU!$H$5107:$H$5107,JU!$F$5107:$F$5107,WS!$A33) -> 0 | T33: =SUMIFS(JU!$K$5107:$K$5107,JU!$I$5107:$I$5107,WS!$A33) -> 0 | U33: =R33+S33-T33 -> 0 | V33: =SUMIFS(JU!$H$5107:$H$5107,JU!$F$5107:$F$5107,WS!$A33) -> 0 | W33: =SUMIFS(JU!$K$5107:$K$5107,JU!$I$5107:$I$5107,WS!$A33) -> 0 | X33: =U33+V33-W33 -> 0 | Y33: =SUMIFS(JU!$H$5107:$H$5107,JU!$F$5107:$F$5107,WS!$A33) -> 0 | Z33: =SUMIFS(JU!$K$5107:$K$5107,JU!$I$5107:$I$5107,WS!$A33) -> 0 | AA33: =X33+Y33-Z33 -> 0 | AB33: =SUMIFS(JU!$H$5107:$H$5107,JU!$F$5107:$F$5107,WS!$A33) -> 0 | AC33: =SUMIFS(JU!$K$5107:$K$5107,JU!$I$5107:$I$5107,WS!$A33) -> 0 | AD33: =AA33+AB33-AC33 -> 0 | AE33: =SUMIFS(JU!$H$5107:$H$5107,JU!$F$5107:$F$5107,WS!$A33) -> 0 | AF33: =SUMIFS(JU!$K$5107:$K$5107,JU!$I$5107:$I$5107,WS!$A33) -> 0 | AG33: =AD33+AE33-AF33 -> 0 | AH33: =SUMIFS(JU!$H$5107:$H$5107,JU!$F$5107:$F$5107,WS!$A33) -> 0 | AI33: =SUMIFS(JU!$K$5107:$K$5107,JU!$I$5107:$I$5107,WS!$A33) -> 0 | AJ33: =AG33+AH33-AI33 -> 0 | AK33: =SUMIFS(JU!$H$5107:$H$5107,JU!$F$5107:$F$5107,WS!$A33) -> 0 | AL33: =SUMIFS(JU!$K$5107:$K$5107,JU!$I$5107:$I$5107,WS!$A33) -> 0 | AM33: =AJ33+AK33-AL33 -> 0
A34: 1305 | B34: Persediaan Barang dalam Proses | C34: 0 | D34: =SUMIFS(JU!$H$5:$H$178,JU!$F$5:$F$178,WS!$A34) -> 0 | E34: =SUMIFS(JU!$K$5:$K$178,JU!$I$5:$I$178,WS!$A34) -> 0 | F34: =C34+D34-E34 -> 0 | G34: =SUMIFS(JU!$H$180:$H$440,JU!$F$180:$F$440,WS!$A34) -> 0 | H34: =SUMIFS(JU!$K$180:$K$440,JU!$I$180:$I$440,WS!$A34) -> 0 | I34: =F34+G34-H34 -> 0 | J34: =SUMIFS(JU!$H$441:$H$695,JU!$F$441:$F$695,WS!$A34) -> 0 | K34: =SUMIFS(JU!$K$441:$K$695,JU!$I$441:$I$695,WS!$A34) -> 0 | L34: =I34+J34-K34 -> 0 | M34: =SUMIFS(JU!$H$696:$H$1062,JU!$F$696:$F$1062,$A34) -> 0 | N34: =SUMIFS(JU!$K$696:$K$1062,JU!$I$696:$I$1062,WS!$A34) -> 0 | O34: =L34+M34-N34 -> 0 | P34: =SUMIFS(JU!$H$1063:$H$5007,JU!$F$1063:$F$5007,WS!$A34) -> 0 | Q34: =SUMIFS(JU!$K$1063:$K$5007,JU!$I$1063:$I$5007,WS!$A34) -> 0 | R34: =O34+P34-Q34 -> 0 | S34: =SUMIFS(JU!$H$5107:$H$5107,JU!$F$5107:$F$5107,WS!$A34) -> 0 | T34: =SUMIFS(JU!$K$5107:$K$5107,JU!$I$5107:$I$5107,WS!$A34) -> 0 | U34: =R34+S34-T34 -> 0 | V34: =SUMIFS(JU!$H$5107:$H$5107,JU!$F$5107:$F$5107,WS!$A34) -> 0 | W34: =SUMIFS(JU!$K$5107:$K$5107,JU!$I$5107:$I$5107,WS!$A34) -> 0 | X34: =U34+V34-W34 -> 0 | Y34: =SUMIFS(JU!$H$5107:$H$5107,JU!$F$5107:$F$5107,WS!$A34) -> 0 | Z34: =SUMIFS(JU!$K$5107:$K$5107,JU!$I$5107:$I$5107,WS!$A34) -> 0 | AA34: =X34+Y34-Z34 -> 0 | AB34: =SUMIFS(JU!$H$5107:$H$5107,JU!$F$5107:$F$5107,WS!$A34) -> 0 | AC34: =SUMIFS(JU!$K$5107:$K$5107,JU!$I$5107:$I$5107,WS!$A34) -> 0 | AD34: =AA34+AB34-AC34 -> 0 | AE34: =SUMIFS(JU!$H$5107:$H$5107,JU!$F$5107:$F$5107,WS!$A34) -> 0 | AF34: =SUMIFS(JU!$K$5107:$K$5107,JU!$I$5107:$I$5107,WS!$A34) -> 0 | AG34: =AD34+AE34-AF34 -> 0 | AH34: =SUMIFS(JU!$H$5107:$H$5107,JU!$F$5107:$F$5107,WS!$A34) -> 0 | AI34: =SUMIFS(JU!$K$5107:$K$5107,JU!$I$5107:$I$5107,WS!$A34) -> 0 | AJ34: =AG34+AH34-AI34 -> 0 | AK34: =SUMIFS(JU!$H$5107:$H$5107,JU!$F$5107:$F$5107,WS!$A34) -> 0 | AL34: =SUMIFS(JU!$K$5107:$K$5107,JU!$I$5107:$I$5107,WS!$A34) -> 0 | AM34: =AJ34+AK34-AL34 -> 0
A35: 1306 | B35: Persediaan Barang Jadi | C35: 0 | D35: =SUMIFS(JU!$H$5:$H$178,JU!$F$5:$F$178,WS!$A35) -> 0 | E35: =SUMIFS(JU!$K$5:$K$178,JU!$I$5:$I$178,WS!$A35) -> 0 | F35: =C35+D35-E35 -> 0 | G35: =SUMIFS(JU!$H$180:$H$440,JU!$F$180:$F$440,WS!$A35) -> 0 | H35: =SUMIFS(JU!$K$180:$K$440,JU!$I$180:$I$440,WS!$A35) -> 0 | I35: =F35+G35-H35 -> 0 | J35: =SUMIFS(JU!$H$441:$H$695,JU!$F$441:$F$695,WS!$A35) -> 0 | K35: =SUMIFS(JU!$K$441:$K$695,JU!$I$441:$I$695,WS!$A35) -> 0 | L35: =I35+J35-K35 -> 0 | M35: =SUMIFS(JU!$H$696:$H$1062,JU!$F$696:$F$1062,$A35) -> 0 | N35: =SUMIFS(JU!$K$696:$K$1062,JU!$I$696:$I$1062,WS!$A35) -> 0 | O35: =L35+M35-N35 -> 0 | P35: =SUMIFS(JU!$H$1063:$H$5007,JU!$F$1063:$F$5007,WS!$A35) -> 0 | Q35: =SUMIFS(JU!$K$1063:$K$5007,JU!$I$1063:$I$5007,WS!$A35) -> 0 | R35: =O35+P35-Q35 -> 0 | S35: =SUMIFS(JU!$H$5107:$H$5107,JU!$F$5107:$F$5107,WS!$A35) -> 0 | T35: =SUMIFS(JU!$K$5107:$K$5107,JU!$I$5107:$I$5107,WS!$A35) -> 0 | U35: =R35+S35-T35 -> 0 | V35: =SUMIFS(JU!$H$5107:$H$5107,JU!$F$5107:$F$5107,WS!$A35) -> 0 | W35: =SUMIFS(JU!$K$5107:$K$5107,JU!$I$5107:$I$5107,WS!$A35) -> 0 | X35: =U35+V35-W35 -> 0 | Y35: =SUMIFS(JU!$H$5107:$H$5107,JU!$F$5107:$F$5107,WS!$A35) -> 0 | Z35: =SUMIFS(JU!$K$5107:$K$5107,JU!$I$5107:$I$5107,WS!$A35) -> 0 | AA35: =X35+Y35-Z35 -> 0 | AB35: =SUMIFS(JU!$H$5107:$H$5107,JU!$F$5107:$F$5107,WS!$A35) -> 0 | AC35: =SUMIFS(JU!$K$5107:$K$5107,JU!$I$5107:$I$5107,WS!$A35) -> 0 | AD35: =AA35+AB35-AC35 -> 0 | AE35: =SUMIFS(JU!$H$5107:$H$5107,JU!$F$5107:$F$5107,WS!$A35) -> 0 | AF35: =SUMIFS(JU!$K$5107:$K$5107,JU!$I$5107:$I$5107,WS!$A35) -> 0 | AG35: =AD35+AE35-AF35 -> 0 | AH35: =SUMIFS(JU!$H$5107:$H$5107,JU!$F$5107:$F$5107,WS!$A35) -> 0 | AI35: =SUMIFS(JU!$K$5107:$K$5107,JU!$I$5107:$I$5107,WS!$A35) -> 0 | AJ35: =AG35+AH35-AI35 -> 0 | AK35: =SUMIFS(JU!$H$5107:$H$5107,JU!$F$5107:$F$5107,WS!$A35) -> 0 | AL35: =SUMIFS(JU!$K$5107:$K$5107,JU!$I$5107:$I$5107,WS!$A35) -> 0 | AM35: =AJ35+AK35-AL35 -> 0
